[2025-08-12T11:22:54.217+0000] {local_task_job_runner.py:120} INFO - ::group::Pre task execution logs
[2025-08-12T11:22:54.250+0000] {taskinstance.py:2076} INFO - Dependencies all met for dep_context=non-requeueable deps ti=<TaskInstance: solar_flares_train_12h.train_notebook scheduled__2025-08-11T12:00:00+00:00 [queued]>
[2025-08-12T11:22:54.259+0000] {taskinstance.py:2076} INFO - Dependencies all met for dep_context=requeueable deps ti=<TaskInstance: solar_flares_train_12h.train_notebook scheduled__2025-08-11T12:00:00+00:00 [queued]>
[2025-08-12T11:22:54.260+0000] {taskinstance.py:2306} INFO - Starting attempt 5 of 7
[2025-08-12T11:22:54.273+0000] {taskinstance.py:2330} INFO - Executing <Task(BashOperator): train_notebook> on 2025-08-11 12:00:00+00:00
[2025-08-12T11:22:54.284+0000] {logging_mixin.py:188} WARNING - /home/***/.local/lib/python3.12/site-packages/***/task/task_runner/standard_task_runner.py:61 DeprecationWarning: This process (pid=1132) is multi-threaded, use of fork() may lead to deadlocks in the child.
[2025-08-12T11:22:54.282+0000] {standard_task_runner.py:90} INFO - Running: ['***', 'tasks', 'run', 'solar_flares_train_12h', 'train_notebook', 'scheduled__2025-08-11T12:00:00+00:00', '--job-id', '111', '--raw', '--subdir', 'DAGS_FOLDER/solar_flares_train_12h.py', '--cfg-path', '/tmp/tmpryue_hx9']
[2025-08-12T11:22:54.285+0000] {standard_task_runner.py:63} INFO - Started process 1133 to run task
[2025-08-12T11:22:54.285+0000] {standard_task_runner.py:91} INFO - Job 111: Subtask train_notebook
[2025-08-12T11:22:54.334+0000] {task_command.py:426} INFO - Running <TaskInstance: solar_flares_train_12h.train_notebook scheduled__2025-08-11T12:00:00+00:00 [running]> on host 72ec96fe1e37
[2025-08-12T11:22:54.416+0000] {taskinstance.py:2648} INFO - Exporting env vars: AIRFLOW_CTX_DAG_OWNER='you' AIRFLOW_CTX_DAG_ID='solar_flares_train_12h' AIRFLOW_CTX_TASK_ID='train_notebook' AIRFLOW_CTX_EXECUTION_DATE='2025-08-11T12:00:00+00:00' AIRFLOW_CTX_TRY_NUMBER='5' AIRFLOW_CTX_DAG_RUN_ID='scheduled__2025-08-11T12:00:00+00:00'
[2025-08-12T11:22:54.420+0000] {taskinstance.py:430} INFO - ::endgroup::
[2025-08-12T11:22:54.433+0000] {subprocess.py:63} INFO - Tmp dir root location: /tmp
[2025-08-12T11:22:54.435+0000] {subprocess.py:75} INFO - Running command: ['/usr/bin/bash', '-c', '\nset -e\nexport PATH="$HOME/.local/bin:$PATH"\nmkdir -p /opt/project/notebooks/runs\ncd /opt/project/notebooks\nOUT="ml_x_ray_sensor_run_20250811T120000.ipynb"\npython -m papermill -k *** ml_x_ray_sensor.ipynb "$OUT"\necho "Notebook exécuté -> $OUT"']
[2025-08-12T11:22:54.446+0000] {subprocess.py:86} INFO - Output:
[2025-08-12T11:22:55.644+0000] {subprocess.py:93} INFO - Input Notebook:  ml_x_ray_sensor.ipynb
[2025-08-12T11:22:55.645+0000] {subprocess.py:93} INFO - Output Notebook: ml_x_ray_sensor_run_20250811T120000.ipynb
[2025-08-12T11:22:56.070+0000] {subprocess.py:93} INFO - Executing:   0%|          | 0/21 [00:00<?, ?cell/s]Failed to run command:
[2025-08-12T11:22:56.074+0000] {subprocess.py:93} INFO - ['', '-Xfrozen_modules=off', '-m', 'ipykernel_launcher', '-f', '/tmp/tmpq5ef4ii8.json']
[2025-08-12T11:22:56.075+0000] {subprocess.py:93} INFO -     PATH='/.local/bin:/usr/local/bin:/usr/local/sbin:/usr/bin:/usr/sbin:/bin:/sbin:.'
[2025-08-12T11:22:56.075+0000] {subprocess.py:93} INFO -     with kwargs:
[2025-08-12T11:22:56.075+0000] {subprocess.py:93} INFO - {'stdin': -1, 'stdout': None, 'stderr': None, 'cwd': None, 'start_new_session': True}
[2025-08-12T11:22:56.076+0000] {subprocess.py:93} INFO - 
[2025-08-12T11:22:56.076+0000] {subprocess.py:93} INFO - [Errno 13] Permission denied: ''
[2025-08-12T11:22:56.076+0000] {subprocess.py:93} INFO - Traceback (most recent call last):
[2025-08-12T11:22:56.077+0000] {subprocess.py:93} INFO -   File "/home/***/.local/lib/python3.12/site-packages/jupyter_core/utils/__init__.py", line 154, in wrapped
[2025-08-12T11:22:56.077+0000] {subprocess.py:93} INFO -     asyncio.get_running_loop()
[2025-08-12T11:22:56.077+0000] {subprocess.py:93} INFO - RuntimeError: no running event loop
[2025-08-12T11:22:56.078+0000] {subprocess.py:93} INFO - 
[2025-08-12T11:22:56.078+0000] {subprocess.py:93} INFO - During handling of the above exception, another exception occurred:
[2025-08-12T11:22:56.078+0000] {subprocess.py:93} INFO - 
[2025-08-12T11:22:56.078+0000] {subprocess.py:93} INFO - Traceback (most recent call last):
[2025-08-12T11:22:56.079+0000] {subprocess.py:93} INFO -   File "/home/***/.local/lib/python3.12/site-packages/jupyter_client/manager.py", line 87, in wrapper
[2025-08-12T11:22:56.079+0000] {subprocess.py:93} INFO -     out = await method(self, *args, **kwargs)
[2025-08-12T11:22:56.079+0000] {subprocess.py:93} INFO -           ^^^^^^^^^^^^^^^^^^^^^^^^^^^^^^^^^^^
[2025-08-12T11:22:56.079+0000] {subprocess.py:93} INFO -   File "/home/***/.local/lib/python3.12/site-packages/jupyter_client/manager.py", line 439, in _async_start_kernel
[2025-08-12T11:22:56.079+0000] {subprocess.py:93} INFO -     await self._async_launch_kernel(kernel_cmd, **kw)
[2025-08-12T11:22:56.080+0000] {subprocess.py:93} INFO -   File "/home/***/.local/lib/python3.12/site-packages/jupyter_client/manager.py", line 354, in _async_launch_kernel
[2025-08-12T11:22:56.080+0000] {subprocess.py:93} INFO -     connection_info = await self.provisioner.launch_kernel(kernel_cmd, **kw)
[2025-08-12T11:22:56.080+0000] {subprocess.py:93} INFO -                       ^^^^^^^^^^^^^^^^^^^^^^^^^^^^^^^^^^^^^^^^^^^^^^^^^^^^^^
[2025-08-12T11:22:56.080+0000] {subprocess.py:93} INFO -   File "/home/***/.local/lib/python3.12/site-packages/jupyter_client/provisioning/local_provisioner.py", line 210, in launch_kernel
[2025-08-12T11:22:56.081+0000] {subprocess.py:93} INFO -     self.process = launch_kernel(cmd, **scrubbed_kwargs)
[2025-08-12T11:22:56.081+0000] {subprocess.py:93} INFO -                    ^^^^^^^^^^^^^^^^^^^^^^^^^^^^^^^^^^^^^
[2025-08-12T11:22:56.081+0000] {subprocess.py:93} INFO -   File "/home/***/.local/lib/python3.12/site-packages/jupyter_client/launcher.py", line 170, in launch_kernel
[2025-08-12T11:22:56.081+0000] {subprocess.py:93} INFO -     raise ex
[2025-08-12T11:22:56.082+0000] {subprocess.py:93} INFO -   File "/home/***/.local/lib/python3.12/site-packages/jupyter_client/launcher.py", line 155, in launch_kernel
[2025-08-12T11:22:56.082+0000] {subprocess.py:93} INFO -     proc = Popen(cmd, **kwargs)  # noqa
[2025-08-12T11:22:56.082+0000] {subprocess.py:93} INFO -            ^^^^^^^^^^^^^^^^^^^^
[2025-08-12T11:22:56.083+0000] {subprocess.py:93} INFO -   File "/usr/local/lib/python3.12/subprocess.py", line 1026, in __init__
[2025-08-12T11:22:56.083+0000] {subprocess.py:93} INFO -     self._execute_child(args, executable, preexec_fn, close_fds,
[2025-08-12T11:22:56.083+0000] {subprocess.py:93} INFO -   File "/usr/local/lib/python3.12/subprocess.py", line 1955, in _execute_child
[2025-08-12T11:22:56.084+0000] {subprocess.py:93} INFO -     raise child_exception_type(errno_num, err_msg, err_filename)
[2025-08-12T11:22:56.084+0000] {subprocess.py:93} INFO - PermissionError: [Errno 13] Permission denied: ''
[2025-08-12T11:22:56.084+0000] {subprocess.py:93} INFO - Executing:   0%|          | 0/21 [00:00<?, ?cell/s]
[2025-08-12T11:22:56.084+0000] {subprocess.py:93} INFO - Traceback (most recent call last):
[2025-08-12T11:22:56.084+0000] {subprocess.py:93} INFO -   File "/home/***/.local/lib/python3.12/site-packages/jupyter_core/utils/__init__.py", line 154, in wrapped
[2025-08-12T11:22:56.084+0000] {subprocess.py:93} INFO -     asyncio.get_running_loop()
[2025-08-12T11:22:56.085+0000] {subprocess.py:93} INFO - RuntimeError: no running event loop
[2025-08-12T11:22:56.085+0000] {subprocess.py:93} INFO - 
[2025-08-12T11:22:56.085+0000] {subprocess.py:93} INFO - During handling of the above exception, another exception occurred:
[2025-08-12T11:22:56.085+0000] {subprocess.py:93} INFO - 
[2025-08-12T11:22:56.085+0000] {subprocess.py:93} INFO - Traceback (most recent call last):
[2025-08-12T11:22:56.086+0000] {subprocess.py:93} INFO -   File "<frozen runpy>", line 198, in _run_module_as_main
[2025-08-12T11:22:56.086+0000] {subprocess.py:93} INFO -   File "<frozen runpy>", line 88, in _run_code
[2025-08-12T11:22:56.086+0000] {subprocess.py:93} INFO -   File "/home/***/.local/lib/python3.12/site-packages/papermill/__main__.py", line 4, in <module>
[2025-08-12T11:22:56.087+0000] {subprocess.py:93} INFO -     papermill()
[2025-08-12T11:22:56.087+0000] {subprocess.py:93} INFO -   File "/home/***/.local/lib/python3.12/site-packages/click/core.py", line 1157, in __call__
[2025-08-12T11:22:56.087+0000] {subprocess.py:93} INFO -     return self.main(*args, **kwargs)
[2025-08-12T11:22:56.087+0000] {subprocess.py:93} INFO -            ^^^^^^^^^^^^^^^^^^^^^^^^^^
[2025-08-12T11:22:56.087+0000] {subprocess.py:93} INFO -   File "/home/***/.local/lib/python3.12/site-packages/click/core.py", line 1078, in main
[2025-08-12T11:22:56.088+0000] {subprocess.py:93} INFO -     rv = self.invoke(ctx)
[2025-08-12T11:22:56.088+0000] {subprocess.py:93} INFO -          ^^^^^^^^^^^^^^^^
[2025-08-12T11:22:56.088+0000] {subprocess.py:93} INFO -   File "/home/***/.local/lib/python3.12/site-packages/click/core.py", line 1434, in invoke
[2025-08-12T11:22:56.088+0000] {subprocess.py:93} INFO -     return ctx.invoke(self.callback, **ctx.params)
[2025-08-12T11:22:56.088+0000] {subprocess.py:93} INFO -            ^^^^^^^^^^^^^^^^^^^^^^^^^^^^^^^^^^^^^^^
[2025-08-12T11:22:56.089+0000] {subprocess.py:93} INFO -   File "/home/***/.local/lib/python3.12/site-packages/click/core.py", line 783, in invoke
[2025-08-12T11:22:56.089+0000] {subprocess.py:93} INFO -     return __callback(*args, **kwargs)
[2025-08-12T11:22:56.089+0000] {subprocess.py:93} INFO -            ^^^^^^^^^^^^^^^^^^^^^^^^^^^
[2025-08-12T11:22:56.090+0000] {subprocess.py:93} INFO -   File "/home/***/.local/lib/python3.12/site-packages/click/decorators.py", line 33, in new_func
[2025-08-12T11:22:56.090+0000] {subprocess.py:93} INFO -     return f(get_current_context(), *args, **kwargs)
[2025-08-12T11:22:56.090+0000] {subprocess.py:93} INFO -            ^^^^^^^^^^^^^^^^^^^^^^^^^^^^^^^^^^^^^^^^^
[2025-08-12T11:22:56.091+0000] {subprocess.py:93} INFO -   File "/home/***/.local/lib/python3.12/site-packages/papermill/cli.py", line 235, in papermill
[2025-08-12T11:22:56.091+0000] {subprocess.py:93} INFO -     execute_notebook(
[2025-08-12T11:22:56.091+0000] {subprocess.py:93} INFO -   File "/home/***/.local/lib/python3.12/site-packages/papermill/execute.py", line 116, in execute_notebook
[2025-08-12T11:22:56.092+0000] {subprocess.py:93} INFO -     nb = papermill_engines.execute_notebook_with_engine(
[2025-08-12T11:22:56.092+0000] {subprocess.py:93} INFO -          ^^^^^^^^^^^^^^^^^^^^^^^^^^^^^^^^^^^^^^^^^^^^^^^
[2025-08-12T11:22:56.092+0000] {subprocess.py:93} INFO -   File "/home/***/.local/lib/python3.12/site-packages/papermill/engines.py", line 48, in execute_notebook_with_engine
[2025-08-12T11:22:56.092+0000] {subprocess.py:93} INFO -     return self.get_engine(engine_name).execute_notebook(nb, kernel_name, **kwargs)
[2025-08-12T11:22:56.092+0000] {subprocess.py:93} INFO -            ^^^^^^^^^^^^^^^^^^^^^^^^^^^^^^^^^^^^^^^^^^^^^^^^^^^^^^^^^^^^^^^^^^^^^^^^
[2025-08-12T11:22:56.092+0000] {subprocess.py:93} INFO -   File "/home/***/.local/lib/python3.12/site-packages/papermill/engines.py", line 370, in execute_notebook
[2025-08-12T11:22:56.093+0000] {subprocess.py:93} INFO -     cls.execute_managed_notebook(nb_man, kernel_name, log_output=log_output, **kwargs)
[2025-08-12T11:22:56.093+0000] {subprocess.py:93} INFO -   File "/home/***/.local/lib/python3.12/site-packages/papermill/engines.py", line 442, in execute_managed_notebook
[2025-08-12T11:22:56.093+0000] {subprocess.py:93} INFO -     return PapermillNotebookClient(nb_man, **final_kwargs).execute()
[2025-08-12T11:22:56.094+0000] {subprocess.py:93} INFO -            ^^^^^^^^^^^^^^^^^^^^^^^^^^^^^^^^^^^^^^^^^^^^^^^^^^^^^^^^^
[2025-08-12T11:22:56.094+0000] {subprocess.py:93} INFO -   File "/home/***/.local/lib/python3.12/site-packages/papermill/clientwrap.py", line 43, in execute
[2025-08-12T11:22:56.094+0000] {subprocess.py:93} INFO -     with self.setup_kernel(**kwargs):
[2025-08-12T11:22:56.094+0000] {subprocess.py:93} INFO -   File "/usr/local/lib/python3.12/contextlib.py", line 137, in __enter__
[2025-08-12T11:22:56.095+0000] {subprocess.py:93} INFO -     return next(self.gen)
[2025-08-12T11:22:56.095+0000] {subprocess.py:93} INFO -            ^^^^^^^^^^^^^^
[2025-08-12T11:22:56.095+0000] {subprocess.py:93} INFO -   File "/home/***/.local/lib/python3.12/site-packages/nbclient/client.py", line 600, in setup_kernel
[2025-08-12T11:22:56.096+0000] {subprocess.py:93} INFO -     self.start_new_kernel(**kwargs)
[2025-08-12T11:22:56.096+0000] {subprocess.py:93} INFO -   File "/home/***/.local/lib/python3.12/site-packages/jupyter_core/utils/__init__.py", line 158, in wrapped
[2025-08-12T11:22:56.096+0000] {subprocess.py:93} INFO -     return loop.run_until_complete(inner)
[2025-08-12T11:22:56.097+0000] {subprocess.py:93} INFO -            ^^^^^^^^^^^^^^^^^^^^^^^^^^^^^^
[2025-08-12T11:22:56.097+0000] {subprocess.py:93} INFO -   File "/usr/local/lib/python3.12/asyncio/base_events.py", line 687, in run_until_complete
[2025-08-12T11:22:56.097+0000] {subprocess.py:93} INFO -     return future.result()
[2025-08-12T11:22:56.097+0000] {subprocess.py:93} INFO -            ^^^^^^^^^^^^^^^
[2025-08-12T11:22:56.098+0000] {subprocess.py:93} INFO -   File "/home/***/.local/lib/python3.12/site-packages/nbclient/client.py", line 550, in async_start_new_kernel
[2025-08-12T11:22:56.098+0000] {subprocess.py:93} INFO -     await ensure_async(self.km.start_kernel(extra_arguments=self.extra_arguments, **kwargs))
[2025-08-12T11:22:56.098+0000] {subprocess.py:93} INFO -   File "/home/***/.local/lib/python3.12/site-packages/jupyter_core/utils/__init__.py", line 197, in ensure_async
[2025-08-12T11:22:56.098+0000] {subprocess.py:93} INFO -     result = await obj
[2025-08-12T11:22:56.099+0000] {subprocess.py:93} INFO -              ^^^^^^^^^
[2025-08-12T11:22:56.099+0000] {subprocess.py:93} INFO -   File "/home/***/.local/lib/python3.12/site-packages/jupyter_client/manager.py", line 96, in wrapper
[2025-08-12T11:22:56.099+0000] {subprocess.py:93} INFO -     raise e
[2025-08-12T11:22:56.099+0000] {subprocess.py:93} INFO -   File "/home/***/.local/lib/python3.12/site-packages/jupyter_client/manager.py", line 87, in wrapper
[2025-08-12T11:22:56.100+0000] {subprocess.py:93} INFO -     out = await method(self, *args, **kwargs)
[2025-08-12T11:22:56.100+0000] {subprocess.py:93} INFO -           ^^^^^^^^^^^^^^^^^^^^^^^^^^^^^^^^^^^
[2025-08-12T11:22:56.100+0000] {subprocess.py:93} INFO -   File "/home/***/.local/lib/python3.12/site-packages/jupyter_client/manager.py", line 439, in _async_start_kernel
[2025-08-12T11:22:56.100+0000] {subprocess.py:93} INFO -     await self._async_launch_kernel(kernel_cmd, **kw)
[2025-08-12T11:22:56.100+0000] {subprocess.py:93} INFO -   File "/home/***/.local/lib/python3.12/site-packages/jupyter_client/manager.py", line 354, in _async_launch_kernel
[2025-08-12T11:22:56.101+0000] {subprocess.py:93} INFO -     connection_info = await self.provisioner.launch_kernel(kernel_cmd, **kw)
[2025-08-12T11:22:56.101+0000] {subprocess.py:93} INFO -                       ^^^^^^^^^^^^^^^^^^^^^^^^^^^^^^^^^^^^^^^^^^^^^^^^^^^^^^
[2025-08-12T11:22:56.101+0000] {subprocess.py:93} INFO -   File "/home/***/.local/lib/python3.12/site-packages/jupyter_client/provisioning/local_provisioner.py", line 210, in launch_kernel
[2025-08-12T11:22:56.101+0000] {subprocess.py:93} INFO -     self.process = launch_kernel(cmd, **scrubbed_kwargs)
[2025-08-12T11:22:56.102+0000] {subprocess.py:93} INFO -                    ^^^^^^^^^^^^^^^^^^^^^^^^^^^^^^^^^^^^^
[2025-08-12T11:22:56.102+0000] {subprocess.py:93} INFO -   File "/home/***/.local/lib/python3.12/site-packages/jupyter_client/launcher.py", line 170, in launch_kernel
[2025-08-12T11:22:56.102+0000] {subprocess.py:93} INFO -     raise ex
[2025-08-12T11:22:56.103+0000] {subprocess.py:93} INFO -   File "/home/***/.local/lib/python3.12/site-packages/jupyter_client/launcher.py", line 155, in launch_kernel
[2025-08-12T11:22:56.103+0000] {subprocess.py:93} INFO -     proc = Popen(cmd, **kwargs)  # noqa
[2025-08-12T11:22:56.103+0000] {subprocess.py:93} INFO -            ^^^^^^^^^^^^^^^^^^^^
[2025-08-12T11:22:56.103+0000] {subprocess.py:93} INFO -   File "/usr/local/lib/python3.12/subprocess.py", line 1026, in __init__
[2025-08-12T11:22:56.104+0000] {subprocess.py:93} INFO -     self._execute_child(args, executable, preexec_fn, close_fds,
[2025-08-12T11:22:56.104+0000] {subprocess.py:93} INFO -   File "/usr/local/lib/python3.12/subprocess.py", line 1955, in _execute_child
[2025-08-12T11:22:56.104+0000] {subprocess.py:93} INFO -     raise child_exception_type(errno_num, err_msg, err_filename)
[2025-08-12T11:22:56.104+0000] {subprocess.py:93} INFO - PermissionError: [Errno 13] Permission denied: ''
[2025-08-12T11:22:56.268+0000] {subprocess.py:97} INFO - Command exited with return code 1
[2025-08-12T11:22:56.269+0000] {taskinstance.py:441} INFO - ::group::Post task execution logs
[2025-08-12T11:22:56.279+0000] {taskinstance.py:2905} ERROR - Task failed with exception
Traceback (most recent call last):
  File "/home/airflow/.local/lib/python3.12/site-packages/airflow/models/taskinstance.py", line 460, in _execute_task
    result = _execute_callable(context=context, **execute_callable_kwargs)
             ^^^^^^^^^^^^^^^^^^^^^^^^^^^^^^^^^^^^^^^^^^^^^^^^^^^^^^^^^^^^^
  File "/home/airflow/.local/lib/python3.12/site-packages/airflow/models/taskinstance.py", line 432, in _execute_callable
    return execute_callable(context=context, **execute_callable_kwargs)
           ^^^^^^^^^^^^^^^^^^^^^^^^^^^^^^^^^^^^^^^^^^^^^^^^^^^^^^^^^^^^
  File "/home/airflow/.local/lib/python3.12/site-packages/airflow/models/baseoperator.py", line 401, in wrapper
    return func(self, *args, **kwargs)
           ^^^^^^^^^^^^^^^^^^^^^^^^^^^
  File "/home/airflow/.local/lib/python3.12/site-packages/airflow/operators/bash.py", line 243, in execute
    raise AirflowException(
airflow.exceptions.AirflowException: Bash command failed. The command returned a non-zero exit code 1.
[2025-08-12T11:22:56.282+0000] {taskinstance.py:1206} INFO - Marking task as UP_FOR_RETRY. dag_id=solar_flares_train_12h, task_id=train_notebook, run_id=scheduled__2025-08-11T12:00:00+00:00, execution_date=20250811T120000, start_date=20250812T112254, end_date=20250812T112256
[2025-08-12T11:22:56.294+0000] {standard_task_runner.py:110} ERROR - Failed to execute job 111 for task train_notebook (Bash command failed. The command returned a non-zero exit code 1.; 1133)
[2025-08-12T11:22:56.303+0000] {local_task_job_runner.py:240} INFO - Task exited with return code 1
[2025-08-12T11:22:56.319+0000] {taskinstance.py:3503} INFO - 0 downstream tasks scheduled from follow-on schedule check
[2025-08-12T11:22:56.321+0000] {local_task_job_runner.py:222} INFO - ::endgroup::
