[2025-08-12T11:07:33.004+0000] {local_task_job_runner.py:120} INFO - ::group::Pre task execution logs
[2025-08-12T11:07:33.050+0000] {taskinstance.py:2076} INFO - Dependencies all met for dep_context=non-requeueable deps ti=<TaskInstance: solar_flares_train_12h.train_notebook scheduled__2025-08-11T12:00:00+00:00 [queued]>
[2025-08-12T11:07:33.063+0000] {taskinstance.py:2076} INFO - Dependencies all met for dep_context=requeueable deps ti=<TaskInstance: solar_flares_train_12h.train_notebook scheduled__2025-08-11T12:00:00+00:00 [queued]>
[2025-08-12T11:07:33.072+0000] {taskinstance.py:2306} INFO - Starting attempt 2 of 4
[2025-08-12T11:07:33.089+0000] {taskinstance.py:2330} INFO - Executing <Task(BashOperator): train_notebook> on 2025-08-11 12:00:00+00:00
[2025-08-12T11:07:33.099+0000] {standard_task_runner.py:90} INFO - Running: ['***', 'tasks', 'run', 'solar_flares_train_12h', 'train_notebook', 'scheduled__2025-08-11T12:00:00+00:00', '--job-id', '104', '--raw', '--subdir', 'DAGS_FOLDER/solar_flares_train_12h.py', '--cfg-path', '/tmp/tmphqmvg1fx']
[2025-08-12T11:07:33.103+0000] {standard_task_runner.py:91} INFO - Job 104: Subtask train_notebook
[2025-08-12T11:07:33.103+0000] {logging_mixin.py:188} WARNING - /home/***/.local/lib/python3.12/site-packages/***/task/task_runner/standard_task_runner.py:61 DeprecationWarning: This process (pid=695) is multi-threaded, use of fork() may lead to deadlocks in the child.
[2025-08-12T11:07:33.104+0000] {standard_task_runner.py:63} INFO - Started process 701 to run task
[2025-08-12T11:07:33.170+0000] {task_command.py:426} INFO - Running <TaskInstance: solar_flares_train_12h.train_notebook scheduled__2025-08-11T12:00:00+00:00 [running]> on host 72ec96fe1e37
[2025-08-12T11:07:33.290+0000] {taskinstance.py:2648} INFO - Exporting env vars: AIRFLOW_CTX_DAG_OWNER='you' AIRFLOW_CTX_DAG_ID='solar_flares_train_12h' AIRFLOW_CTX_TASK_ID='train_notebook' AIRFLOW_CTX_EXECUTION_DATE='2025-08-11T12:00:00+00:00' AIRFLOW_CTX_TRY_NUMBER='2' AIRFLOW_CTX_DAG_RUN_ID='scheduled__2025-08-11T12:00:00+00:00'
[2025-08-12T11:07:33.291+0000] {taskinstance.py:430} INFO - ::endgroup::
[2025-08-12T11:07:33.309+0000] {subprocess.py:63} INFO - Tmp dir root location: /tmp
[2025-08-12T11:07:33.311+0000] {subprocess.py:75} INFO - Running command: ['/usr/bin/bash', '-c', '\nset -e\nexport PATH="$HOME/.local/bin:$PATH"\nmkdir -p /opt/project/notebooks/runs\ncd /opt/project/notebooks\nOUT="ml_x_ray_sensor_run_20250811T120000.ipynb"\npython -m papermill -k python3 ml_x_ray_sensor.ipynb "$OUT"\necho "Notebook exécuté -> $OUT"']
[2025-08-12T11:07:33.325+0000] {subprocess.py:86} INFO - Output:
[2025-08-12T11:07:36.457+0000] {subprocess.py:93} INFO - Input Notebook:  ml_x_ray_sensor.ipynb
[2025-08-12T11:07:36.458+0000] {subprocess.py:93} INFO - Output Notebook: ml_x_ray_sensor_run_20250811T120000.ipynb
[2025-08-12T11:07:36.588+0000] {subprocess.py:93} INFO - Executing:   0%|          | 0/21 [00:00<?, ?cell/s]Kernelspec name python3 cannot be found!
[2025-08-12T11:07:36.590+0000] {subprocess.py:93} INFO - No such kernel named python3
[2025-08-12T11:07:36.590+0000] {subprocess.py:93} INFO - Traceback (most recent call last):
[2025-08-12T11:07:36.591+0000] {subprocess.py:93} INFO -   File "/home/***/.local/lib/python3.12/site-packages/jupyter_core/utils/__init__.py", line 154, in wrapped
[2025-08-12T11:07:36.592+0000] {subprocess.py:93} INFO -     asyncio.get_running_loop()
[2025-08-12T11:07:36.592+0000] {subprocess.py:93} INFO - RuntimeError: no running event loop
[2025-08-12T11:07:36.592+0000] {subprocess.py:93} INFO - 
[2025-08-12T11:07:36.593+0000] {subprocess.py:93} INFO - During handling of the above exception, another exception occurred:
[2025-08-12T11:07:36.593+0000] {subprocess.py:93} INFO - 
[2025-08-12T11:07:36.594+0000] {subprocess.py:93} INFO - Traceback (most recent call last):
[2025-08-12T11:07:36.595+0000] {subprocess.py:93} INFO -   File "/home/***/.local/lib/python3.12/site-packages/jupyter_client/manager.py", line 87, in wrapper
[2025-08-12T11:07:36.595+0000] {subprocess.py:93} INFO -     out = await method(self, *args, **kwargs)
[2025-08-12T11:07:36.596+0000] {subprocess.py:93} INFO -           ^^^^^^^^^^^^^^^^^^^^^^^^^^^^^^^^^^^
[2025-08-12T11:07:36.596+0000] {subprocess.py:93} INFO -   File "/home/***/.local/lib/python3.12/site-packages/jupyter_client/manager.py", line 435, in _async_start_kernel
[2025-08-12T11:07:36.597+0000] {subprocess.py:93} INFO -     kernel_cmd, kw = await self._async_pre_start_kernel(**kw)
[2025-08-12T11:07:36.597+0000] {subprocess.py:93} INFO -                      ^^^^^^^^^^^^^^^^^^^^^^^^^^^^^^^^^^^^^^^^
[2025-08-12T11:07:36.597+0000] {subprocess.py:93} INFO -   File "/home/***/.local/lib/python3.12/site-packages/jupyter_client/manager.py", line 397, in _async_pre_start_kernel
[2025-08-12T11:07:36.598+0000] {subprocess.py:93} INFO -     self.kernel_spec,
[2025-08-12T11:07:36.598+0000] {subprocess.py:93} INFO -     ^^^^^^^^^^^^^^^^
[2025-08-12T11:07:36.599+0000] {subprocess.py:93} INFO -   File "/home/***/.local/lib/python3.12/site-packages/jupyter_client/manager.py", line 195, in kernel_spec
[2025-08-12T11:07:36.600+0000] {subprocess.py:93} INFO -     self._kernel_spec = self.kernel_spec_manager.get_kernel_spec(self.kernel_name)
[2025-08-12T11:07:36.600+0000] {subprocess.py:93} INFO -                         ^^^^^^^^^^^^^^^^^^^^^^^^^^^^^^^^^^^^^^^^^^^^^^^^^^^^^^^^^^
[2025-08-12T11:07:36.602+0000] {subprocess.py:93} INFO -   File "/home/***/.local/lib/python3.12/site-packages/jupyter_client/kernelspec.py", line 285, in get_kernel_spec
[2025-08-12T11:07:36.603+0000] {subprocess.py:93} INFO -     raise NoSuchKernel(kernel_name)
[2025-08-12T11:07:36.603+0000] {subprocess.py:93} INFO - jupyter_client.kernelspec.NoSuchKernel: No such kernel named python3
[2025-08-12T11:07:36.604+0000] {subprocess.py:93} INFO - Executing:   0%|          | 0/21 [00:00<?, ?cell/s]
[2025-08-12T11:07:36.604+0000] {subprocess.py:93} INFO - Traceback (most recent call last):
[2025-08-12T11:07:36.605+0000] {subprocess.py:93} INFO -   File "/home/***/.local/lib/python3.12/site-packages/jupyter_core/utils/__init__.py", line 154, in wrapped
[2025-08-12T11:07:36.605+0000] {subprocess.py:93} INFO -     asyncio.get_running_loop()
[2025-08-12T11:07:36.606+0000] {subprocess.py:93} INFO - RuntimeError: no running event loop
[2025-08-12T11:07:36.607+0000] {subprocess.py:93} INFO - 
[2025-08-12T11:07:36.607+0000] {subprocess.py:93} INFO - During handling of the above exception, another exception occurred:
[2025-08-12T11:07:36.607+0000] {subprocess.py:93} INFO - 
[2025-08-12T11:07:36.608+0000] {subprocess.py:93} INFO - Traceback (most recent call last):
[2025-08-12T11:07:36.608+0000] {subprocess.py:93} INFO -   File "<frozen runpy>", line 198, in _run_module_as_main
[2025-08-12T11:07:36.609+0000] {subprocess.py:93} INFO -   File "<frozen runpy>", line 88, in _run_code
[2025-08-12T11:07:36.609+0000] {subprocess.py:93} INFO -   File "/home/***/.local/lib/python3.12/site-packages/papermill/__main__.py", line 4, in <module>
[2025-08-12T11:07:36.610+0000] {subprocess.py:93} INFO -     papermill()
[2025-08-12T11:07:36.610+0000] {subprocess.py:93} INFO -   File "/home/***/.local/lib/python3.12/site-packages/click/core.py", line 1157, in __call__
[2025-08-12T11:07:36.610+0000] {subprocess.py:93} INFO -     return self.main(*args, **kwargs)
[2025-08-12T11:07:36.611+0000] {subprocess.py:93} INFO -            ^^^^^^^^^^^^^^^^^^^^^^^^^^
[2025-08-12T11:07:36.611+0000] {subprocess.py:93} INFO -   File "/home/***/.local/lib/python3.12/site-packages/click/core.py", line 1078, in main
[2025-08-12T11:07:36.612+0000] {subprocess.py:93} INFO -     rv = self.invoke(ctx)
[2025-08-12T11:07:36.612+0000] {subprocess.py:93} INFO -          ^^^^^^^^^^^^^^^^
[2025-08-12T11:07:36.613+0000] {subprocess.py:93} INFO -   File "/home/***/.local/lib/python3.12/site-packages/click/core.py", line 1434, in invoke
[2025-08-12T11:07:36.613+0000] {subprocess.py:93} INFO -     return ctx.invoke(self.callback, **ctx.params)
[2025-08-12T11:07:36.613+0000] {subprocess.py:93} INFO -            ^^^^^^^^^^^^^^^^^^^^^^^^^^^^^^^^^^^^^^^
[2025-08-12T11:07:36.614+0000] {subprocess.py:93} INFO -   File "/home/***/.local/lib/python3.12/site-packages/click/core.py", line 783, in invoke
[2025-08-12T11:07:36.615+0000] {subprocess.py:93} INFO -     return __callback(*args, **kwargs)
[2025-08-12T11:07:36.615+0000] {subprocess.py:93} INFO -            ^^^^^^^^^^^^^^^^^^^^^^^^^^^
[2025-08-12T11:07:36.616+0000] {subprocess.py:93} INFO -   File "/home/***/.local/lib/python3.12/site-packages/click/decorators.py", line 33, in new_func
[2025-08-12T11:07:36.616+0000] {subprocess.py:93} INFO -     return f(get_current_context(), *args, **kwargs)
[2025-08-12T11:07:36.617+0000] {subprocess.py:93} INFO -            ^^^^^^^^^^^^^^^^^^^^^^^^^^^^^^^^^^^^^^^^^
[2025-08-12T11:07:36.617+0000] {subprocess.py:93} INFO -   File "/home/***/.local/lib/python3.12/site-packages/papermill/cli.py", line 235, in papermill
[2025-08-12T11:07:36.617+0000] {subprocess.py:93} INFO -     execute_notebook(
[2025-08-12T11:07:36.618+0000] {subprocess.py:93} INFO -   File "/home/***/.local/lib/python3.12/site-packages/papermill/execute.py", line 116, in execute_notebook
[2025-08-12T11:07:36.618+0000] {subprocess.py:93} INFO -     nb = papermill_engines.execute_notebook_with_engine(
[2025-08-12T11:07:36.619+0000] {subprocess.py:93} INFO -          ^^^^^^^^^^^^^^^^^^^^^^^^^^^^^^^^^^^^^^^^^^^^^^^
[2025-08-12T11:07:36.619+0000] {subprocess.py:93} INFO -   File "/home/***/.local/lib/python3.12/site-packages/papermill/engines.py", line 48, in execute_notebook_with_engine
[2025-08-12T11:07:36.620+0000] {subprocess.py:93} INFO -     return self.get_engine(engine_name).execute_notebook(nb, kernel_name, **kwargs)
[2025-08-12T11:07:36.620+0000] {subprocess.py:93} INFO -            ^^^^^^^^^^^^^^^^^^^^^^^^^^^^^^^^^^^^^^^^^^^^^^^^^^^^^^^^^^^^^^^^^^^^^^^^
[2025-08-12T11:07:36.621+0000] {subprocess.py:93} INFO -   File "/home/***/.local/lib/python3.12/site-packages/papermill/engines.py", line 370, in execute_notebook
[2025-08-12T11:07:36.621+0000] {subprocess.py:93} INFO -     cls.execute_managed_notebook(nb_man, kernel_name, log_output=log_output, **kwargs)
[2025-08-12T11:07:36.622+0000] {subprocess.py:93} INFO -   File "/home/***/.local/lib/python3.12/site-packages/papermill/engines.py", line 442, in execute_managed_notebook
[2025-08-12T11:07:36.622+0000] {subprocess.py:93} INFO -     return PapermillNotebookClient(nb_man, **final_kwargs).execute()
[2025-08-12T11:07:36.623+0000] {subprocess.py:93} INFO -            ^^^^^^^^^^^^^^^^^^^^^^^^^^^^^^^^^^^^^^^^^^^^^^^^^^^^^^^^^
[2025-08-12T11:07:36.623+0000] {subprocess.py:93} INFO -   File "/home/***/.local/lib/python3.12/site-packages/papermill/clientwrap.py", line 43, in execute
[2025-08-12T11:07:36.624+0000] {subprocess.py:93} INFO -     with self.setup_kernel(**kwargs):
[2025-08-12T11:07:36.624+0000] {subprocess.py:93} INFO -   File "/usr/local/lib/python3.12/contextlib.py", line 137, in __enter__
[2025-08-12T11:07:36.624+0000] {subprocess.py:93} INFO -     return next(self.gen)
[2025-08-12T11:07:36.625+0000] {subprocess.py:93} INFO -            ^^^^^^^^^^^^^^
[2025-08-12T11:07:36.625+0000] {subprocess.py:93} INFO -   File "/home/***/.local/lib/python3.12/site-packages/nbclient/client.py", line 600, in setup_kernel
[2025-08-12T11:07:36.625+0000] {subprocess.py:93} INFO -     self.start_new_kernel(**kwargs)
[2025-08-12T11:07:36.626+0000] {subprocess.py:93} INFO -   File "/home/***/.local/lib/python3.12/site-packages/jupyter_core/utils/__init__.py", line 158, in wrapped
[2025-08-12T11:07:36.626+0000] {subprocess.py:93} INFO -     return loop.run_until_complete(inner)
[2025-08-12T11:07:36.627+0000] {subprocess.py:93} INFO -            ^^^^^^^^^^^^^^^^^^^^^^^^^^^^^^
[2025-08-12T11:07:36.627+0000] {subprocess.py:93} INFO -   File "/usr/local/lib/python3.12/asyncio/base_events.py", line 687, in run_until_complete
[2025-08-12T11:07:36.627+0000] {subprocess.py:93} INFO -     return future.result()
[2025-08-12T11:07:36.628+0000] {subprocess.py:93} INFO -            ^^^^^^^^^^^^^^^
[2025-08-12T11:07:36.628+0000] {subprocess.py:93} INFO -   File "/home/***/.local/lib/python3.12/site-packages/nbclient/client.py", line 550, in async_start_new_kernel
[2025-08-12T11:07:36.629+0000] {subprocess.py:93} INFO -     await ensure_async(self.km.start_kernel(extra_arguments=self.extra_arguments, **kwargs))
[2025-08-12T11:07:36.629+0000] {subprocess.py:93} INFO -   File "/home/***/.local/lib/python3.12/site-packages/jupyter_core/utils/__init__.py", line 197, in ensure_async
[2025-08-12T11:07:36.630+0000] {subprocess.py:93} INFO -     result = await obj
[2025-08-12T11:07:36.631+0000] {subprocess.py:93} INFO -              ^^^^^^^^^
[2025-08-12T11:07:36.631+0000] {subprocess.py:93} INFO -   File "/home/***/.local/lib/python3.12/site-packages/jupyter_client/manager.py", line 96, in wrapper
[2025-08-12T11:07:36.632+0000] {subprocess.py:93} INFO -     raise e
[2025-08-12T11:07:36.633+0000] {subprocess.py:93} INFO -   File "/home/***/.local/lib/python3.12/site-packages/jupyter_client/manager.py", line 87, in wrapper
[2025-08-12T11:07:36.633+0000] {subprocess.py:93} INFO -     out = await method(self, *args, **kwargs)
[2025-08-12T11:07:36.634+0000] {subprocess.py:93} INFO -           ^^^^^^^^^^^^^^^^^^^^^^^^^^^^^^^^^^^
[2025-08-12T11:07:36.634+0000] {subprocess.py:93} INFO -   File "/home/***/.local/lib/python3.12/site-packages/jupyter_client/manager.py", line 435, in _async_start_kernel
[2025-08-12T11:07:36.635+0000] {subprocess.py:93} INFO -     kernel_cmd, kw = await self._async_pre_start_kernel(**kw)
[2025-08-12T11:07:36.635+0000] {subprocess.py:93} INFO -                      ^^^^^^^^^^^^^^^^^^^^^^^^^^^^^^^^^^^^^^^^
[2025-08-12T11:07:36.636+0000] {subprocess.py:93} INFO -   File "/home/***/.local/lib/python3.12/site-packages/jupyter_client/manager.py", line 397, in _async_pre_start_kernel
[2025-08-12T11:07:36.636+0000] {subprocess.py:93} INFO -     self.kernel_spec,
[2025-08-12T11:07:36.636+0000] {subprocess.py:93} INFO -     ^^^^^^^^^^^^^^^^
[2025-08-12T11:07:36.637+0000] {subprocess.py:93} INFO -   File "/home/***/.local/lib/python3.12/site-packages/jupyter_client/manager.py", line 195, in kernel_spec
[2025-08-12T11:07:36.637+0000] {subprocess.py:93} INFO -     self._kernel_spec = self.kernel_spec_manager.get_kernel_spec(self.kernel_name)
[2025-08-12T11:07:36.638+0000] {subprocess.py:93} INFO -                         ^^^^^^^^^^^^^^^^^^^^^^^^^^^^^^^^^^^^^^^^^^^^^^^^^^^^^^^^^^
[2025-08-12T11:07:36.638+0000] {subprocess.py:93} INFO -   File "/home/***/.local/lib/python3.12/site-packages/jupyter_client/kernelspec.py", line 285, in get_kernel_spec
[2025-08-12T11:07:36.639+0000] {subprocess.py:93} INFO -     raise NoSuchKernel(kernel_name)
[2025-08-12T11:07:36.640+0000] {subprocess.py:93} INFO - jupyter_client.kernelspec.NoSuchKernel: No such kernel named python3
[2025-08-12T11:07:36.834+0000] {subprocess.py:97} INFO - Command exited with return code 1
[2025-08-12T11:07:36.835+0000] {taskinstance.py:441} INFO - ::group::Post task execution logs
[2025-08-12T11:07:36.848+0000] {taskinstance.py:2905} ERROR - Task failed with exception
Traceback (most recent call last):
  File "/home/airflow/.local/lib/python3.12/site-packages/airflow/models/taskinstance.py", line 460, in _execute_task
    result = _execute_callable(context=context, **execute_callable_kwargs)
             ^^^^^^^^^^^^^^^^^^^^^^^^^^^^^^^^^^^^^^^^^^^^^^^^^^^^^^^^^^^^^
  File "/home/airflow/.local/lib/python3.12/site-packages/airflow/models/taskinstance.py", line 432, in _execute_callable
    return execute_callable(context=context, **execute_callable_kwargs)
           ^^^^^^^^^^^^^^^^^^^^^^^^^^^^^^^^^^^^^^^^^^^^^^^^^^^^^^^^^^^^
  File "/home/airflow/.local/lib/python3.12/site-packages/airflow/models/baseoperator.py", line 401, in wrapper
    return func(self, *args, **kwargs)
           ^^^^^^^^^^^^^^^^^^^^^^^^^^^
  File "/home/airflow/.local/lib/python3.12/site-packages/airflow/operators/bash.py", line 243, in execute
    raise AirflowException(
airflow.exceptions.AirflowException: Bash command failed. The command returned a non-zero exit code 1.
[2025-08-12T11:07:36.853+0000] {taskinstance.py:1206} INFO - Marking task as UP_FOR_RETRY. dag_id=solar_flares_train_12h, task_id=train_notebook, run_id=scheduled__2025-08-11T12:00:00+00:00, execution_date=20250811T120000, start_date=20250812T110733, end_date=20250812T110736
[2025-08-12T11:07:36.869+0000] {standard_task_runner.py:110} ERROR - Failed to execute job 104 for task train_notebook (Bash command failed. The command returned a non-zero exit code 1.; 701)
[2025-08-12T11:07:36.890+0000] {local_task_job_runner.py:240} INFO - Task exited with return code 1
[2025-08-12T11:07:36.909+0000] {taskinstance.py:3503} INFO - 0 downstream tasks scheduled from follow-on schedule check
[2025-08-12T11:07:36.913+0000] {local_task_job_runner.py:222} INFO - ::endgroup::
