[2025-08-12T11:02:27.644+0000] {local_task_job_runner.py:120} INFO - ::group::Pre task execution logs
[2025-08-12T11:02:27.679+0000] {taskinstance.py:2076} INFO - Dependencies all met for dep_context=non-requeueable deps ti=<TaskInstance: solar_flares_train_12h.train_notebook scheduled__2025-08-11T12:00:00+00:00 [queued]>
[2025-08-12T11:02:27.690+0000] {taskinstance.py:2076} INFO - Dependencies all met for dep_context=requeueable deps ti=<TaskInstance: solar_flares_train_12h.train_notebook scheduled__2025-08-11T12:00:00+00:00 [queued]>
[2025-08-12T11:02:27.691+0000] {taskinstance.py:2306} INFO - Starting attempt 1 of 3
[2025-08-12T11:02:27.704+0000] {taskinstance.py:2330} INFO - Executing <Task(BashOperator): train_notebook> on 2025-08-11 12:00:00+00:00
[2025-08-12T11:02:27.717+0000] {standard_task_runner.py:90} INFO - Running: ['***', 'tasks', 'run', 'solar_flares_train_12h', 'train_notebook', 'scheduled__2025-08-11T12:00:00+00:00', '--job-id', '103', '--raw', '--subdir', 'DAGS_FOLDER/solar_flares_train_12h.py', '--cfg-path', '/tmp/tmpml431pdd']
[2025-08-12T11:02:27.719+0000] {logging_mixin.py:188} WARNING - /home/***/.local/lib/python3.12/site-packages/***/task/task_runner/standard_task_runner.py:61 DeprecationWarning: This process (pid=579) is multi-threaded, use of fork() may lead to deadlocks in the child.
[2025-08-12T11:02:27.720+0000] {standard_task_runner.py:91} INFO - Job 103: Subtask train_notebook
[2025-08-12T11:02:27.720+0000] {standard_task_runner.py:63} INFO - Started process 580 to run task
[2025-08-12T11:02:27.822+0000] {task_command.py:426} INFO - Running <TaskInstance: solar_flares_train_12h.train_notebook scheduled__2025-08-11T12:00:00+00:00 [running]> on host 72ec96fe1e37
[2025-08-12T11:02:27.980+0000] {taskinstance.py:2648} INFO - Exporting env vars: AIRFLOW_CTX_DAG_OWNER='you' AIRFLOW_CTX_DAG_ID='solar_flares_train_12h' AIRFLOW_CTX_TASK_ID='train_notebook' AIRFLOW_CTX_EXECUTION_DATE='2025-08-11T12:00:00+00:00' AIRFLOW_CTX_TRY_NUMBER='1' AIRFLOW_CTX_DAG_RUN_ID='scheduled__2025-08-11T12:00:00+00:00'
[2025-08-12T11:02:27.984+0000] {taskinstance.py:430} INFO - ::endgroup::
[2025-08-12T11:02:28.006+0000] {subprocess.py:63} INFO - Tmp dir root location: /tmp
[2025-08-12T11:02:28.008+0000] {subprocess.py:75} INFO - Running command: ['/usr/bin/bash', '-c', '\nset -e\nmkdir -p /opt/project/notebooks/runs\ncd /opt/project/notebooks\nOUT="ml_x_ray_sensor_run_20250811T120000.ipynb"\npapermill ml_x_ray_sensor.ipynb "$OUT"\necho "Notebook exécuté -> $OUT"']
[2025-08-12T11:02:28.023+0000] {subprocess.py:86} INFO - Output:
[2025-08-12T11:02:28.034+0000] {subprocess.py:93} INFO - /usr/bin/bash: line 6: papermill: command not found
[2025-08-12T11:02:28.035+0000] {subprocess.py:97} INFO - Command exited with return code 127
[2025-08-12T11:02:28.036+0000] {taskinstance.py:441} INFO - ::group::Post task execution logs
[2025-08-12T11:02:28.050+0000] {taskinstance.py:2905} ERROR - Task failed with exception
Traceback (most recent call last):
  File "/home/airflow/.local/lib/python3.12/site-packages/airflow/models/taskinstance.py", line 460, in _execute_task
    result = _execute_callable(context=context, **execute_callable_kwargs)
             ^^^^^^^^^^^^^^^^^^^^^^^^^^^^^^^^^^^^^^^^^^^^^^^^^^^^^^^^^^^^^
  File "/home/airflow/.local/lib/python3.12/site-packages/airflow/models/taskinstance.py", line 432, in _execute_callable
    return execute_callable(context=context, **execute_callable_kwargs)
           ^^^^^^^^^^^^^^^^^^^^^^^^^^^^^^^^^^^^^^^^^^^^^^^^^^^^^^^^^^^^
  File "/home/airflow/.local/lib/python3.12/site-packages/airflow/models/baseoperator.py", line 401, in wrapper
    return func(self, *args, **kwargs)
           ^^^^^^^^^^^^^^^^^^^^^^^^^^^
  File "/home/airflow/.local/lib/python3.12/site-packages/airflow/operators/bash.py", line 243, in execute
    raise AirflowException(
airflow.exceptions.AirflowException: Bash command failed. The command returned a non-zero exit code 127.
[2025-08-12T11:02:28.057+0000] {taskinstance.py:1206} INFO - Marking task as UP_FOR_RETRY. dag_id=solar_flares_train_12h, task_id=train_notebook, run_id=scheduled__2025-08-11T12:00:00+00:00, execution_date=20250811T120000, start_date=20250812T110227, end_date=20250812T110228
[2025-08-12T11:02:28.074+0000] {standard_task_runner.py:110} ERROR - Failed to execute job 103 for task train_notebook (Bash command failed. The command returned a non-zero exit code 127.; 580)
[2025-08-12T11:02:28.094+0000] {local_task_job_runner.py:240} INFO - Task exited with return code 1
[2025-08-12T11:02:27.881+0000] {taskinstance.py:3503} INFO - 0 downstream tasks scheduled from follow-on schedule check
[2025-08-12T11:02:27.884+0000] {local_task_job_runner.py:222} INFO - ::endgroup::
