[2025-08-09T20:05:30.888+0000] {local_task_job_runner.py:120} INFO - ::group::Pre task execution logs
[2025-08-09T20:05:30.915+0000] {taskinstance.py:2076} INFO - Dependencies all met for dep_context=non-requeueable deps ti=<TaskInstance: xrs_update_12h.backfill_ncei_j2 manual__2025-08-09T19:53:05+00:00 [queued]>
[2025-08-09T20:05:30.922+0000] {taskinstance.py:2076} INFO - Dependencies all met for dep_context=requeueable deps ti=<TaskInstance: xrs_update_12h.backfill_ncei_j2 manual__2025-08-09T19:53:05+00:00 [queued]>
[2025-08-09T20:05:30.924+0000] {taskinstance.py:2306} INFO - Starting attempt 1 of 3
[2025-08-09T20:05:30.936+0000] {taskinstance.py:2330} INFO - Executing <Task(BashOperator): backfill_ncei_j2> on 2025-08-09 19:53:05+00:00
[2025-08-09T20:05:30.946+0000] {logging_mixin.py:188} WARNING - /home/***/.local/lib/python3.12/site-packages/***/task/task_runner/standard_task_runner.py:61 DeprecationWarning: This process (pid=421) is multi-threaded, use of fork() may lead to deadlocks in the child.
[2025-08-09T20:05:30.944+0000] {standard_task_runner.py:90} INFO - Running: ['***', 'tasks', 'run', 'xrs_update_12h', 'backfill_ncei_j2', 'manual__2025-08-09T19:53:05+00:00', '--job-id', '71', '--raw', '--subdir', 'DAGS_FOLDER/xrs_update_daily.py', '--cfg-path', '/tmp/tmpsk__kk25']
[2025-08-09T20:05:30.947+0000] {standard_task_runner.py:63} INFO - Started process 422 to run task
[2025-08-09T20:05:30.947+0000] {standard_task_runner.py:91} INFO - Job 71: Subtask backfill_ncei_j2
[2025-08-09T20:05:30.993+0000] {task_command.py:426} INFO - Running <TaskInstance: xrs_update_12h.backfill_ncei_j2 manual__2025-08-09T19:53:05+00:00 [running]> on host 9d4e07229e62
[2025-08-09T20:05:31.080+0000] {taskinstance.py:2648} INFO - Exporting env vars: AIRFLOW_CTX_DAG_OWNER='you' AIRFLOW_CTX_DAG_ID='xrs_update_12h' AIRFLOW_CTX_TASK_ID='backfill_ncei_j2' AIRFLOW_CTX_EXECUTION_DATE='2025-08-09T19:53:05+00:00' AIRFLOW_CTX_TRY_NUMBER='1' AIRFLOW_CTX_DAG_RUN_ID='manual__2025-08-09T19:53:05+00:00'
[2025-08-09T20:05:31.081+0000] {taskinstance.py:430} INFO - ::endgroup::
[2025-08-09T20:05:31.092+0000] {subprocess.py:63} INFO - Tmp dir root location: /tmp
[2025-08-09T20:05:31.093+0000] {subprocess.py:75} INFO - Running command: ['/usr/bin/bash', '-c', 'python /opt/project/src/data/xrs_update.py --mode backfill --start 2025-08-07 --end 2025-08-07']
[2025-08-09T20:05:31.106+0000] {subprocess.py:86} INFO - Output:
[2025-08-09T20:05:33.465+0000] {local_task_job_runner.py:124} ERROR - Received SIGTERM. Terminating subprocesses
[2025-08-09T20:05:33.470+0000] {process_utils.py:132} INFO - Sending 15 to group 422. PIDs of all processes in the group: [423, 422]
[2025-08-09T20:05:33.471+0000] {process_utils.py:87} INFO - Sending the signal 15 to group 422
[2025-08-09T20:05:33.472+0000] {taskinstance.py:2611} ERROR - Received SIGTERM. Terminating subprocesses.
[2025-08-09T20:05:33.472+0000] {subprocess.py:104} INFO - Sending SIGTERM signal to process group
[2025-08-09T20:05:33.473+0000] {taskinstance.py:441} INFO - ::group::Post task execution logs
[2025-08-09T20:05:33.486+0000] {taskinstance.py:2905} ERROR - Task failed with exception
Traceback (most recent call last):
  File "/home/airflow/.local/lib/python3.12/site-packages/airflow/models/taskinstance.py", line 465, in _execute_task
    result = _execute_callable(context=context, **execute_callable_kwargs)
             ^^^^^^^^^^^^^^^^^^^^^^^^^^^^^^^^^^^^^^^^^^^^^^^^^^^^^^^^^^^^^
  File "/home/airflow/.local/lib/python3.12/site-packages/airflow/models/taskinstance.py", line 432, in _execute_callable
    return execute_callable(context=context, **execute_callable_kwargs)
           ^^^^^^^^^^^^^^^^^^^^^^^^^^^^^^^^^^^^^^^^^^^^^^^^^^^^^^^^^^^^
  File "/home/airflow/.local/lib/python3.12/site-packages/airflow/models/baseoperator.py", line 401, in wrapper
    return func(self, *args, **kwargs)
           ^^^^^^^^^^^^^^^^^^^^^^^^^^^
  File "/home/airflow/.local/lib/python3.12/site-packages/airflow/operators/bash.py", line 234, in execute
    result = self.subprocess_hook.run_command(
             ^^^^^^^^^^^^^^^^^^^^^^^^^^^^^^^^^
  File "/home/airflow/.local/lib/python3.12/site-packages/airflow/hooks/subprocess.py", line 91, in run_command
    for raw_line in iter(self.sub_process.stdout.readline, b""):
  File "/home/airflow/.local/lib/python3.12/site-packages/airflow/models/taskinstance.py", line 2613, in signal_handler
    raise AirflowTaskTerminated("Task received SIGTERM signal")
airflow.exceptions.AirflowTaskTerminated: Task received SIGTERM signal
[2025-08-09T20:05:33.491+0000] {taskinstance.py:1206} INFO - Marking task as UP_FOR_RETRY. dag_id=xrs_update_12h, task_id=backfill_ncei_j2, run_id=manual__2025-08-09T19:53:05+00:00, execution_date=20250809T195305, start_date=20250809T200530, end_date=20250809T200533
[2025-08-09T20:05:33.524+0000] {process_utils.py:80} INFO - Process psutil.Process(pid=423, status='terminated', started='20:05:30') (423) terminated with exit code None
[2025-08-09T20:05:33.524+0000] {process_utils.py:80} INFO - Process psutil.Process(pid=422, status='terminated', exitcode=2, started='20:05:30') (422) terminated with exit code 2
[2025-08-09T20:05:33.525+0000] {local_task_job_runner.py:240} INFO - Task exited with return code 143
[2025-08-09T20:05:33.544+0000] {taskinstance.py:3503} INFO - 0 downstream tasks scheduled from follow-on schedule check
