[2025-08-12T13:24:51.267+0000] {local_task_job_runner.py:120} INFO - ::group::Pre task execution logs
[2025-08-12T13:24:51.319+0000] {taskinstance.py:2076} INFO - Dependencies all met for dep_context=non-requeueable deps ti=<TaskInstance: solar_flares_train_12h.train_notebook scheduled__2025-08-12T00:00:00+00:00 [queued]>
[2025-08-12T13:24:51.328+0000] {taskinstance.py:2076} INFO - Dependencies all met for dep_context=requeueable deps ti=<TaskInstance: solar_flares_train_12h.train_notebook scheduled__2025-08-12T00:00:00+00:00 [queued]>
[2025-08-12T13:24:51.329+0000] {taskinstance.py:2306} INFO - Starting attempt 7 of 9
[2025-08-12T13:24:51.341+0000] {taskinstance.py:2330} INFO - Executing <Task(BashOperator): train_notebook> on 2025-08-12 00:00:00+00:00
[2025-08-12T13:24:51.352+0000] {logging_mixin.py:188} WARNING - /home/***/.local/lib/python3.12/site-packages/***/task/task_runner/standard_task_runner.py:61 DeprecationWarning: This process (pid=4671) is multi-threaded, use of fork() may lead to deadlocks in the child.
[2025-08-12T13:24:51.350+0000] {standard_task_runner.py:90} INFO - Running: ['***', 'tasks', 'run', 'solar_flares_train_12h', 'train_notebook', 'scheduled__2025-08-12T00:00:00+00:00', '--job-id', '133', '--raw', '--subdir', 'DAGS_FOLDER/solar_flares_train_12h.py', '--cfg-path', '/tmp/tmppgwyd1rv']
[2025-08-12T13:24:51.353+0000] {standard_task_runner.py:63} INFO - Started process 4672 to run task
[2025-08-12T13:24:51.354+0000] {standard_task_runner.py:91} INFO - Job 133: Subtask train_notebook
[2025-08-12T13:24:51.489+0000] {task_command.py:426} INFO - Running <TaskInstance: solar_flares_train_12h.train_notebook scheduled__2025-08-12T00:00:00+00:00 [running]> on host 72ec96fe1e37
[2025-08-12T13:24:51.632+0000] {taskinstance.py:2648} INFO - Exporting env vars: AIRFLOW_CTX_DAG_OWNER='you' AIRFLOW_CTX_DAG_ID='solar_flares_train_12h' AIRFLOW_CTX_TASK_ID='train_notebook' AIRFLOW_CTX_EXECUTION_DATE='2025-08-12T00:00:00+00:00' AIRFLOW_CTX_TRY_NUMBER='7' AIRFLOW_CTX_DAG_RUN_ID='scheduled__2025-08-12T00:00:00+00:00'
[2025-08-12T13:24:51.635+0000] {taskinstance.py:430} INFO - ::endgroup::
[2025-08-12T13:24:51.671+0000] {subprocess.py:63} INFO - Tmp dir root location: /tmp
[2025-08-12T13:24:51.674+0000] {subprocess.py:75} INFO - Running command: ['/usr/bin/bash', '-c', '\nset -e\nmkdir -p /opt/project/notebooks/runs\ncd /opt/project/notebooks\nOUT="ml_x_ray_sensor_run_20250812T000000.ipynb"\npython -m papermill -k *** ml_x_ray_sensor.ipynb "$OUT"\necho "Notebook exécuté -> $OUT"']
[2025-08-12T13:24:51.695+0000] {subprocess.py:86} INFO - Output:
[2025-08-12T13:24:54.359+0000] {subprocess.py:93} INFO - Input Notebook:  ml_x_ray_sensor.ipynb
[2025-08-12T13:24:54.360+0000] {subprocess.py:93} INFO - Output Notebook: ml_x_ray_sensor_run_20250812T000000.ipynb
[2025-08-12T13:24:56.385+0000] {subprocess.py:93} INFO - Executing:   0%|          | 0/21 [00:00<?, ?cell/s]Executing notebook with kernel: ***
[2025-08-12T13:24:56.772+0000] {subprocess.py:93} INFO - Executing:   5%|▍         | 1/21 [00:02<00:42,  2.13s/cell]Executing:   5%|▍         | 1/21 [00:02<00:46,  2.34s/cell]
[2025-08-12T13:24:56.783+0000] {subprocess.py:93} INFO - Traceback (most recent call last):
[2025-08-12T13:24:56.784+0000] {subprocess.py:93} INFO -   File "<frozen runpy>", line 198, in _run_module_as_main
[2025-08-12T13:24:56.784+0000] {subprocess.py:93} INFO -   File "<frozen runpy>", line 88, in _run_code
[2025-08-12T13:24:56.785+0000] {subprocess.py:93} INFO -   File "/home/***/.local/lib/python3.12/site-packages/papermill/__main__.py", line 4, in <module>
[2025-08-12T13:24:56.785+0000] {subprocess.py:93} INFO -     papermill()
[2025-08-12T13:24:56.785+0000] {subprocess.py:93} INFO -   File "/home/***/.local/lib/python3.12/site-packages/click/core.py", line 1157, in __call__
[2025-08-12T13:24:56.786+0000] {subprocess.py:93} INFO -     return self.main(*args, **kwargs)
[2025-08-12T13:24:56.786+0000] {subprocess.py:93} INFO -            ^^^^^^^^^^^^^^^^^^^^^^^^^^
[2025-08-12T13:24:56.786+0000] {subprocess.py:93} INFO -   File "/home/***/.local/lib/python3.12/site-packages/click/core.py", line 1078, in main
[2025-08-12T13:24:56.786+0000] {subprocess.py:93} INFO -     rv = self.invoke(ctx)
[2025-08-12T13:24:56.787+0000] {subprocess.py:93} INFO -          ^^^^^^^^^^^^^^^^
[2025-08-12T13:24:56.787+0000] {subprocess.py:93} INFO -   File "/home/***/.local/lib/python3.12/site-packages/click/core.py", line 1434, in invoke
[2025-08-12T13:24:56.787+0000] {subprocess.py:93} INFO -     return ctx.invoke(self.callback, **ctx.params)
[2025-08-12T13:24:56.788+0000] {subprocess.py:93} INFO -            ^^^^^^^^^^^^^^^^^^^^^^^^^^^^^^^^^^^^^^^
[2025-08-12T13:24:56.788+0000] {subprocess.py:93} INFO -   File "/home/***/.local/lib/python3.12/site-packages/click/core.py", line 783, in invoke
[2025-08-12T13:24:56.788+0000] {subprocess.py:93} INFO -     return __callback(*args, **kwargs)
[2025-08-12T13:24:56.789+0000] {subprocess.py:93} INFO -            ^^^^^^^^^^^^^^^^^^^^^^^^^^^
[2025-08-12T13:24:56.789+0000] {subprocess.py:93} INFO -   File "/home/***/.local/lib/python3.12/site-packages/click/decorators.py", line 33, in new_func
[2025-08-12T13:24:56.790+0000] {subprocess.py:93} INFO -     return f(get_current_context(), *args, **kwargs)
[2025-08-12T13:24:56.790+0000] {subprocess.py:93} INFO -            ^^^^^^^^^^^^^^^^^^^^^^^^^^^^^^^^^^^^^^^^^
[2025-08-12T13:24:56.790+0000] {subprocess.py:93} INFO -   File "/home/***/.local/lib/python3.12/site-packages/papermill/cli.py", line 235, in papermill
[2025-08-12T13:24:56.790+0000] {subprocess.py:93} INFO -     execute_notebook(
[2025-08-12T13:24:56.791+0000] {subprocess.py:93} INFO -   File "/home/***/.local/lib/python3.12/site-packages/papermill/execute.py", line 131, in execute_notebook
[2025-08-12T13:24:56.791+0000] {subprocess.py:93} INFO -     raise_for_execution_errors(nb, output_path)
[2025-08-12T13:24:56.791+0000] {subprocess.py:93} INFO -   File "/home/***/.local/lib/python3.12/site-packages/papermill/execute.py", line 251, in raise_for_execution_errors
[2025-08-12T13:24:56.791+0000] {subprocess.py:93} INFO -     raise error
[2025-08-12T13:24:56.792+0000] {subprocess.py:93} INFO - papermill.exceptions.PapermillExecutionError:
[2025-08-12T13:24:56.792+0000] {subprocess.py:93} INFO - ---------------------------------------------------------------------------
[2025-08-12T13:24:56.792+0000] {subprocess.py:93} INFO - Exception encountered at "In [1]":
[2025-08-12T13:24:56.792+0000] {subprocess.py:93} INFO - ---------------------------------------------------------------------------
[2025-08-12T13:24:56.793+0000] {subprocess.py:93} INFO - NameError                                 Traceback (most recent call last)
[2025-08-12T13:24:56.793+0000] {subprocess.py:93} INFO - Cell In[1], line 2
[2025-08-12T13:24:56.793+0000] {subprocess.py:93} INFO -       1 # tout en haut du notebook
[2025-08-12T13:24:56.794+0000] {subprocess.py:93} INFO - ----> 2 EXPERIMENT = os.getenv("MLFLOW_EXPERIMENT", "solar-flares-v2")
[2025-08-12T13:24:56.794+0000] {subprocess.py:93} INFO -       3 mlflow.set_tracking_uri(os.getenv("MLFLOW_TRACKING_URI", "http://mlflow:5000"))
[2025-08-12T13:24:56.794+0000] {subprocess.py:93} INFO -       4 mlflow.set_experiment(EXPERIMENT)
[2025-08-12T13:24:56.794+0000] {subprocess.py:93} INFO - 
[2025-08-12T13:24:56.795+0000] {subprocess.py:93} INFO - NameError: name 'os' is not defined
[2025-08-12T13:24:56.795+0000] {subprocess.py:93} INFO - 
[2025-08-12T13:24:57.048+0000] {subprocess.py:97} INFO - Command exited with return code 1
[2025-08-12T13:24:57.050+0000] {taskinstance.py:441} INFO - ::group::Post task execution logs
[2025-08-12T13:24:57.064+0000] {taskinstance.py:2905} ERROR - Task failed with exception
Traceback (most recent call last):
  File "/home/airflow/.local/lib/python3.12/site-packages/airflow/models/taskinstance.py", line 460, in _execute_task
    result = _execute_callable(context=context, **execute_callable_kwargs)
             ^^^^^^^^^^^^^^^^^^^^^^^^^^^^^^^^^^^^^^^^^^^^^^^^^^^^^^^^^^^^^
  File "/home/airflow/.local/lib/python3.12/site-packages/airflow/models/taskinstance.py", line 432, in _execute_callable
    return execute_callable(context=context, **execute_callable_kwargs)
           ^^^^^^^^^^^^^^^^^^^^^^^^^^^^^^^^^^^^^^^^^^^^^^^^^^^^^^^^^^^^
  File "/home/airflow/.local/lib/python3.12/site-packages/airflow/models/baseoperator.py", line 401, in wrapper
    return func(self, *args, **kwargs)
           ^^^^^^^^^^^^^^^^^^^^^^^^^^^
  File "/home/airflow/.local/lib/python3.12/site-packages/airflow/operators/bash.py", line 243, in execute
    raise AirflowException(
airflow.exceptions.AirflowException: Bash command failed. The command returned a non-zero exit code 1.
[2025-08-12T13:24:57.070+0000] {taskinstance.py:1206} INFO - Marking task as UP_FOR_RETRY. dag_id=solar_flares_train_12h, task_id=train_notebook, run_id=scheduled__2025-08-12T00:00:00+00:00, execution_date=20250812T000000, start_date=20250812T132451, end_date=20250812T132457
[2025-08-12T13:24:57.084+0000] {standard_task_runner.py:110} ERROR - Failed to execute job 133 for task train_notebook (Bash command failed. The command returned a non-zero exit code 1.; 4672)
[2025-08-12T13:24:57.106+0000] {local_task_job_runner.py:240} INFO - Task exited with return code 1
[2025-08-12T13:24:57.126+0000] {taskinstance.py:3503} INFO - 0 downstream tasks scheduled from follow-on schedule check
[2025-08-12T13:24:57.129+0000] {local_task_job_runner.py:222} INFO - ::endgroup::
