[2025-08-12T13:12:28.406+0000] {local_task_job_runner.py:120} INFO - ::group::Pre task execution logs
[2025-08-12T13:12:28.441+0000] {taskinstance.py:2076} INFO - Dependencies all met for dep_context=non-requeueable deps ti=<TaskInstance: solar_flares_train_12h.train_notebook scheduled__2025-08-12T00:00:00+00:00 [queued]>
[2025-08-12T13:12:28.450+0000] {taskinstance.py:2076} INFO - Dependencies all met for dep_context=requeueable deps ti=<TaskInstance: solar_flares_train_12h.train_notebook scheduled__2025-08-12T00:00:00+00:00 [queued]>
[2025-08-12T13:12:28.450+0000] {taskinstance.py:2306} INFO - Starting attempt 5 of 7
[2025-08-12T13:12:28.463+0000] {taskinstance.py:2330} INFO - Executing <Task(BashOperator): train_notebook> on 2025-08-12 00:00:00+00:00
[2025-08-12T13:12:28.472+0000] {standard_task_runner.py:90} INFO - Running: ['***', 'tasks', 'run', 'solar_flares_train_12h', 'train_notebook', 'scheduled__2025-08-12T00:00:00+00:00', '--job-id', '131', '--raw', '--subdir', 'DAGS_FOLDER/solar_flares_train_12h.py', '--cfg-path', '/tmp/tmpre_7m2ig']
[2025-08-12T13:12:28.474+0000] {logging_mixin.py:188} WARNING - /home/***/.local/lib/python3.12/site-packages/***/task/task_runner/standard_task_runner.py:61 DeprecationWarning: This process (pid=4246) is multi-threaded, use of fork() may lead to deadlocks in the child.
[2025-08-12T13:12:28.475+0000] {standard_task_runner.py:91} INFO - Job 131: Subtask train_notebook
[2025-08-12T13:12:28.475+0000] {standard_task_runner.py:63} INFO - Started process 4247 to run task
[2025-08-12T13:12:28.529+0000] {task_command.py:426} INFO - Running <TaskInstance: solar_flares_train_12h.train_notebook scheduled__2025-08-12T00:00:00+00:00 [running]> on host 72ec96fe1e37
[2025-08-12T13:12:28.609+0000] {taskinstance.py:2648} INFO - Exporting env vars: AIRFLOW_CTX_DAG_OWNER='you' AIRFLOW_CTX_DAG_ID='solar_flares_train_12h' AIRFLOW_CTX_TASK_ID='train_notebook' AIRFLOW_CTX_EXECUTION_DATE='2025-08-12T00:00:00+00:00' AIRFLOW_CTX_TRY_NUMBER='5' AIRFLOW_CTX_DAG_RUN_ID='scheduled__2025-08-12T00:00:00+00:00'
[2025-08-12T13:12:28.610+0000] {taskinstance.py:430} INFO - ::endgroup::
[2025-08-12T13:12:28.621+0000] {subprocess.py:63} INFO - Tmp dir root location: /tmp
[2025-08-12T13:12:28.623+0000] {subprocess.py:75} INFO - Running command: ['/usr/bin/bash', '-c', '\nset -e\nmkdir -p /opt/project/notebooks/runs\ncd /opt/project/notebooks\nOUT="ml_x_ray_sensor_run_20250812T000000.ipynb"\npython -m papermill -k *** ml_x_ray_sensor.ipynb "$OUT"\necho "Notebook exécuté -> $OUT"']
[2025-08-12T13:12:28.634+0000] {subprocess.py:86} INFO - Output:
[2025-08-12T13:12:29.840+0000] {subprocess.py:93} INFO - Input Notebook:  ml_x_ray_sensor.ipynb
[2025-08-12T13:12:29.841+0000] {subprocess.py:93} INFO - Output Notebook: ml_x_ray_sensor_run_20250812T000000.ipynb
[2025-08-12T13:12:31.566+0000] {subprocess.py:93} INFO - Executing:   0%|          | 0/21 [00:00<?, ?cell/s]Executing notebook with kernel: ***
[2025-08-12T13:13:29.489+0000] {subprocess.py:93} INFO - Executing:   5%|▍         | 1/21 [00:01<00:33,  1.70s/cell]Executing:  10%|▉         | 2/21 [00:05<00:50,  2.65s/cell]Executing:  19%|█▉        | 4/21 [00:05<00:17,  1.03s/cell]Executing:  29%|██▊       | 6/21 [00:06<00:11,  1.32cell/s]Executing:  38%|███▊      | 8/21 [00:06<00:06,  1.96cell/s]Executing:  43%|████▎     | 9/21 [00:06<00:05,  2.22cell/s]Executing:  57%|█████▋    | 12/21 [00:06<00:02,  3.45cell/s]Executing:  71%|███████▏  | 15/21 [00:53<00:39,  6.55s/cell]Executing:  76%|███████▌  | 16/21 [00:53<00:27,  5.50s/cell]Executing:  86%|████████▌ | 18/21 [00:53<00:11,  3.76s/cell]Executing:  90%|█████████ | 19/21 [00:59<00:06,  3.14s/cell]
[2025-08-12T13:13:29.502+0000] {subprocess.py:93} INFO - Traceback (most recent call last):
[2025-08-12T13:13:29.502+0000] {subprocess.py:93} INFO -   File "<frozen runpy>", line 198, in _run_module_as_main
[2025-08-12T13:13:29.503+0000] {subprocess.py:93} INFO -   File "<frozen runpy>", line 88, in _run_code
[2025-08-12T13:13:29.503+0000] {subprocess.py:93} INFO -   File "/home/***/.local/lib/python3.12/site-packages/papermill/__main__.py", line 4, in <module>
[2025-08-12T13:13:29.503+0000] {subprocess.py:93} INFO -     papermill()
[2025-08-12T13:13:29.503+0000] {subprocess.py:93} INFO -   File "/home/***/.local/lib/python3.12/site-packages/click/core.py", line 1157, in __call__
[2025-08-12T13:13:29.504+0000] {subprocess.py:93} INFO -     return self.main(*args, **kwargs)
[2025-08-12T13:13:29.504+0000] {subprocess.py:93} INFO -            ^^^^^^^^^^^^^^^^^^^^^^^^^^
[2025-08-12T13:13:29.504+0000] {subprocess.py:93} INFO -   File "/home/***/.local/lib/python3.12/site-packages/click/core.py", line 1078, in main
[2025-08-12T13:13:29.505+0000] {subprocess.py:93} INFO -     rv = self.invoke(ctx)
[2025-08-12T13:13:29.505+0000] {subprocess.py:93} INFO -          ^^^^^^^^^^^^^^^^
[2025-08-12T13:13:29.505+0000] {subprocess.py:93} INFO -   File "/home/***/.local/lib/python3.12/site-packages/click/core.py", line 1434, in invoke
[2025-08-12T13:13:29.505+0000] {subprocess.py:93} INFO -     return ctx.invoke(self.callback, **ctx.params)
[2025-08-12T13:13:29.506+0000] {subprocess.py:93} INFO -            ^^^^^^^^^^^^^^^^^^^^^^^^^^^^^^^^^^^^^^^
[2025-08-12T13:13:29.506+0000] {subprocess.py:93} INFO -   File "/home/***/.local/lib/python3.12/site-packages/click/core.py", line 783, in invoke
[2025-08-12T13:13:29.506+0000] {subprocess.py:93} INFO -     return __callback(*args, **kwargs)
[2025-08-12T13:13:29.507+0000] {subprocess.py:93} INFO -            ^^^^^^^^^^^^^^^^^^^^^^^^^^^
[2025-08-12T13:13:29.507+0000] {subprocess.py:93} INFO -   File "/home/***/.local/lib/python3.12/site-packages/click/decorators.py", line 33, in new_func
[2025-08-12T13:13:29.507+0000] {subprocess.py:93} INFO -     return f(get_current_context(), *args, **kwargs)
[2025-08-12T13:13:29.507+0000] {subprocess.py:93} INFO -            ^^^^^^^^^^^^^^^^^^^^^^^^^^^^^^^^^^^^^^^^^
[2025-08-12T13:13:29.507+0000] {subprocess.py:93} INFO -   File "/home/***/.local/lib/python3.12/site-packages/papermill/cli.py", line 235, in papermill
[2025-08-12T13:13:29.508+0000] {subprocess.py:93} INFO -     execute_notebook(
[2025-08-12T13:13:29.508+0000] {subprocess.py:93} INFO -   File "/home/***/.local/lib/python3.12/site-packages/papermill/execute.py", line 131, in execute_notebook
[2025-08-12T13:13:29.508+0000] {subprocess.py:93} INFO -     raise_for_execution_errors(nb, output_path)
[2025-08-12T13:13:29.509+0000] {subprocess.py:93} INFO -   File "/home/***/.local/lib/python3.12/site-packages/papermill/execute.py", line 251, in raise_for_execution_errors
[2025-08-12T13:13:29.509+0000] {subprocess.py:93} INFO -     raise error
[2025-08-12T13:13:29.509+0000] {subprocess.py:93} INFO - papermill.exceptions.PapermillExecutionError:
[2025-08-12T13:13:29.509+0000] {subprocess.py:93} INFO - ---------------------------------------------------------------------------
[2025-08-12T13:13:29.509+0000] {subprocess.py:93} INFO - Exception encountered at "In [16]":
[2025-08-12T13:13:29.510+0000] {subprocess.py:93} INFO - ---------------------------------------------------------------------------
[2025-08-12T13:13:29.510+0000] {subprocess.py:93} INFO - PermissionError                           Traceback (most recent call last)
[2025-08-12T13:13:29.510+0000] {subprocess.py:93} INFO - Cell In[16], line 206
[2025-08-12T13:13:29.510+0000] {subprocess.py:93} INFO -     203     try: plt.close(fig)
[2025-08-12T13:13:29.511+0000] {subprocess.py:93} INFO -     204     except Exception: pass
[2025-08-12T13:13:29.511+0000] {subprocess.py:93} INFO - --> 206 _safe_artifact(EVIDENTLY_HTML, artifact_path="evidently")
[2025-08-12T13:13:29.511+0000] {subprocess.py:93} INFO -     207 _safe_artifact(EVIDENTLY_JSON, artifact_path="evidently")
[2025-08-12T13:13:29.511+0000] {subprocess.py:93} INFO -     208 _safe_artifact(MODEL_PATH)
[2025-08-12T13:13:29.512+0000] {subprocess.py:93} INFO - 
[2025-08-12T13:13:29.512+0000] {subprocess.py:93} INFO - Cell In[16], line 189, in _safe_artifact(pth, artifact_path)
[2025-08-12T13:13:29.512+0000] {subprocess.py:93} INFO -     187 p = Path(pth)
[2025-08-12T13:13:29.513+0000] {subprocess.py:93} INFO -     188 if p.exists():
[2025-08-12T13:13:29.513+0000] {subprocess.py:93} INFO - --> 189     mlflow.log_artifact(str(p), artifact_path=artifact_path)
[2025-08-12T13:13:29.513+0000] {subprocess.py:93} INFO -     190 else:
[2025-08-12T13:13:29.513+0000] {subprocess.py:93} INFO -     191     print(f"⚠️ Artefact introuvable: {p}")
[2025-08-12T13:13:29.514+0000] {subprocess.py:93} INFO - 
[2025-08-12T13:13:29.514+0000] {subprocess.py:93} INFO - File ~/.local/lib/python3.12/site-packages/mlflow/tracking/fluent.py:1068, in log_artifact(local_path, artifact_path, run_id)
[2025-08-12T13:13:29.514+0000] {subprocess.py:93} INFO -    1040 """
[2025-08-12T13:13:29.514+0000] {subprocess.py:93} INFO -    1041 Log a local file or directory as an artifact of the currently active run. If no run is
[2025-08-12T13:13:29.515+0000] {subprocess.py:93} INFO -    1042 active, this method will create a new active run.
[2025-08-12T13:13:29.515+0000] {subprocess.py:93} INFO -    (...)   1065             mlflow.log_artifact(path)
[2025-08-12T13:13:29.515+0000] {subprocess.py:93} INFO -    1066 """
[2025-08-12T13:13:29.516+0000] {subprocess.py:93} INFO -    1067 run_id = run_id or _get_or_start_run().info.run_id
[2025-08-12T13:13:29.516+0000] {subprocess.py:93} INFO - -> 1068 MlflowClient().log_artifact(run_id, local_path, artifact_path)
[2025-08-12T13:13:29.516+0000] {subprocess.py:93} INFO - 
[2025-08-12T13:13:29.517+0000] {subprocess.py:93} INFO - File ~/.local/lib/python3.12/site-packages/mlflow/tracking/client.py:1915, in MlflowClient.log_artifact(self, run_id, local_path, artifact_path)
[2025-08-12T13:13:29.517+0000] {subprocess.py:93} INFO -    1911 if run_id.startswith(TRACE_REQUEST_ID_PREFIX):
[2025-08-12T13:13:29.517+0000] {subprocess.py:93} INFO -    1912     raise MlflowException(
[2025-08-12T13:13:29.517+0000] {subprocess.py:93} INFO -    1913         f"Invalid run id: {run_id}. `log_artifact` run id must map to a valid run."
[2025-08-12T13:13:29.518+0000] {subprocess.py:93} INFO -    1914     )
[2025-08-12T13:13:29.518+0000] {subprocess.py:93} INFO - -> 1915 self._tracking_client.log_artifact(run_id, local_path, artifact_path)
[2025-08-12T13:13:29.518+0000] {subprocess.py:93} INFO - 
[2025-08-12T13:13:29.518+0000] {subprocess.py:93} INFO - File ~/.local/lib/python3.12/site-packages/mlflow/tracking/_tracking_service/client.py:810, in TrackingServiceClient.log_artifact(self, run_id, local_path, artifact_path)
[2025-08-12T13:13:29.519+0000] {subprocess.py:93} INFO -     808     artifact_repo.log_artifacts(local_path, path_name)
[2025-08-12T13:13:29.519+0000] {subprocess.py:93} INFO -     809 else:
[2025-08-12T13:13:29.519+0000] {subprocess.py:93} INFO - --> 810     artifact_repo.log_artifact(local_path, artifact_path)
[2025-08-12T13:13:29.519+0000] {subprocess.py:93} INFO - 
[2025-08-12T13:13:29.520+0000] {subprocess.py:93} INFO - File ~/.local/lib/python3.12/site-packages/mlflow/store/artifact/local_artifact_repo.py:43, in LocalArtifactRepository.log_artifact(self, local_file, artifact_path)
[2025-08-12T13:13:29.520+0000] {subprocess.py:93} INFO -      39 artifact_dir = (
[2025-08-12T13:13:29.520+0000] {subprocess.py:93} INFO -      40     os.path.join(self.artifact_dir, artifact_path) if artifact_path else self.artifact_dir
[2025-08-12T13:13:29.521+0000] {subprocess.py:93} INFO -      41 )
[2025-08-12T13:13:29.521+0000] {subprocess.py:93} INFO -      42 if not os.path.exists(artifact_dir):
[2025-08-12T13:13:29.521+0000] {subprocess.py:93} INFO - ---> 43     mkdir(artifact_dir)
[2025-08-12T13:13:29.521+0000] {subprocess.py:93} INFO -      44 try:
[2025-08-12T13:13:29.521+0000] {subprocess.py:93} INFO -      45     shutil.copy2(local_file, os.path.join(artifact_dir, os.path.basename(local_file)))
[2025-08-12T13:13:29.522+0000] {subprocess.py:93} INFO - 
[2025-08-12T13:13:29.522+0000] {subprocess.py:93} INFO - File ~/.local/lib/python3.12/site-packages/mlflow/utils/file_utils.py:214, in mkdir(root, name)
[2025-08-12T13:13:29.522+0000] {subprocess.py:93} INFO -     212 except OSError as e:
[2025-08-12T13:13:29.522+0000] {subprocess.py:93} INFO -     213     if e.errno != errno.EEXIST or not os.path.isdir(target):
[2025-08-12T13:13:29.523+0000] {subprocess.py:93} INFO - --> 214         raise e
[2025-08-12T13:13:29.523+0000] {subprocess.py:93} INFO -     215 return target
[2025-08-12T13:13:29.523+0000] {subprocess.py:93} INFO - 
[2025-08-12T13:13:29.523+0000] {subprocess.py:93} INFO - File ~/.local/lib/python3.12/site-packages/mlflow/utils/file_utils.py:211, in mkdir(root, name)
[2025-08-12T13:13:29.523+0000] {subprocess.py:93} INFO -     209 target = os.path.join(root, name) if name is not None else root
[2025-08-12T13:13:29.524+0000] {subprocess.py:93} INFO -     210 try:
[2025-08-12T13:13:29.524+0000] {subprocess.py:93} INFO - --> 211     os.makedirs(target, exist_ok=True)
[2025-08-12T13:13:29.524+0000] {subprocess.py:93} INFO -     212 except OSError as e:
[2025-08-12T13:13:29.524+0000] {subprocess.py:93} INFO -     213     if e.errno != errno.EEXIST or not os.path.isdir(target):
[2025-08-12T13:13:29.524+0000] {subprocess.py:93} INFO - 
[2025-08-12T13:13:29.525+0000] {subprocess.py:93} INFO - File /usr/local/lib/python3.12/os.py:215, in makedirs(name, mode, exist_ok)
[2025-08-12T13:13:29.525+0000] {subprocess.py:93} INFO -     213 if head and tail and not path.exists(head):
[2025-08-12T13:13:29.525+0000] {subprocess.py:93} INFO -     214     try:
[2025-08-12T13:13:29.525+0000] {subprocess.py:93} INFO - --> 215         makedirs(head, exist_ok=exist_ok)
[2025-08-12T13:13:29.526+0000] {subprocess.py:93} INFO -     216     except FileExistsError:
[2025-08-12T13:13:29.526+0000] {subprocess.py:93} INFO -     217         # Defeats race condition when another thread created the path
[2025-08-12T13:13:29.526+0000] {subprocess.py:93} INFO -     218         pass
[2025-08-12T13:13:29.526+0000] {subprocess.py:93} INFO - 
[2025-08-12T13:13:29.527+0000] {subprocess.py:93} INFO - File /usr/local/lib/python3.12/os.py:215, in makedirs(name, mode, exist_ok)
[2025-08-12T13:13:29.527+0000] {subprocess.py:93} INFO -     213 if head and tail and not path.exists(head):
[2025-08-12T13:13:29.527+0000] {subprocess.py:93} INFO -     214     try:
[2025-08-12T13:13:29.527+0000] {subprocess.py:93} INFO - --> 215         makedirs(head, exist_ok=exist_ok)
[2025-08-12T13:13:29.527+0000] {subprocess.py:93} INFO -     216     except FileExistsError:
[2025-08-12T13:13:29.528+0000] {subprocess.py:93} INFO -     217         # Defeats race condition when another thread created the path
[2025-08-12T13:13:29.528+0000] {subprocess.py:93} INFO -     218         pass
[2025-08-12T13:13:29.528+0000] {subprocess.py:93} INFO - 
[2025-08-12T13:13:29.528+0000] {subprocess.py:93} INFO -     [... skipping similar frames: makedirs at line 215 (2 times)]
[2025-08-12T13:13:29.529+0000] {subprocess.py:93} INFO - 
[2025-08-12T13:13:29.529+0000] {subprocess.py:93} INFO - File /usr/local/lib/python3.12/os.py:215, in makedirs(name, mode, exist_ok)
[2025-08-12T13:13:29.529+0000] {subprocess.py:93} INFO -     213 if head and tail and not path.exists(head):
[2025-08-12T13:13:29.529+0000] {subprocess.py:93} INFO -     214     try:
[2025-08-12T13:13:29.530+0000] {subprocess.py:93} INFO - --> 215         makedirs(head, exist_ok=exist_ok)
[2025-08-12T13:13:29.530+0000] {subprocess.py:93} INFO -     216     except FileExistsError:
[2025-08-12T13:13:29.530+0000] {subprocess.py:93} INFO -     217         # Defeats race condition when another thread created the path
[2025-08-12T13:13:29.530+0000] {subprocess.py:93} INFO -     218         pass
[2025-08-12T13:13:29.530+0000] {subprocess.py:93} INFO - 
[2025-08-12T13:13:29.531+0000] {subprocess.py:93} INFO - File /usr/local/lib/python3.12/os.py:225, in makedirs(name, mode, exist_ok)
[2025-08-12T13:13:29.531+0000] {subprocess.py:93} INFO -     223         return
[2025-08-12T13:13:29.531+0000] {subprocess.py:93} INFO -     224 try:
[2025-08-12T13:13:29.531+0000] {subprocess.py:93} INFO - --> 225     mkdir(name, mode)
[2025-08-12T13:13:29.531+0000] {subprocess.py:93} INFO -     226 except OSError:
[2025-08-12T13:13:29.532+0000] {subprocess.py:93} INFO -     227     # Cannot rely on checking for EEXIST, since the operating system
[2025-08-12T13:13:29.532+0000] {subprocess.py:93} INFO -     228     # could give priority to other errors like EACCES or EROFS
[2025-08-12T13:13:29.532+0000] {subprocess.py:93} INFO -     229     if not exist_ok or not path.isdir(name):
[2025-08-12T13:13:29.533+0000] {subprocess.py:93} INFO - 
[2025-08-12T13:13:29.533+0000] {subprocess.py:93} INFO - PermissionError: [Errno 13] Permission denied: '/mlflow'
[2025-08-12T13:13:29.533+0000] {subprocess.py:93} INFO - 
[2025-08-12T13:13:29.682+0000] {subprocess.py:97} INFO - Command exited with return code 1
[2025-08-12T13:13:29.684+0000] {taskinstance.py:441} INFO - ::group::Post task execution logs
[2025-08-12T13:13:29.696+0000] {taskinstance.py:2905} ERROR - Task failed with exception
Traceback (most recent call last):
  File "/home/airflow/.local/lib/python3.12/site-packages/airflow/models/taskinstance.py", line 460, in _execute_task
    result = _execute_callable(context=context, **execute_callable_kwargs)
             ^^^^^^^^^^^^^^^^^^^^^^^^^^^^^^^^^^^^^^^^^^^^^^^^^^^^^^^^^^^^^
  File "/home/airflow/.local/lib/python3.12/site-packages/airflow/models/taskinstance.py", line 432, in _execute_callable
    return execute_callable(context=context, **execute_callable_kwargs)
           ^^^^^^^^^^^^^^^^^^^^^^^^^^^^^^^^^^^^^^^^^^^^^^^^^^^^^^^^^^^^
  File "/home/airflow/.local/lib/python3.12/site-packages/airflow/models/baseoperator.py", line 401, in wrapper
    return func(self, *args, **kwargs)
           ^^^^^^^^^^^^^^^^^^^^^^^^^^^
  File "/home/airflow/.local/lib/python3.12/site-packages/airflow/operators/bash.py", line 243, in execute
    raise AirflowException(
airflow.exceptions.AirflowException: Bash command failed. The command returned a non-zero exit code 1.
[2025-08-12T13:13:29.699+0000] {taskinstance.py:1206} INFO - Marking task as UP_FOR_RETRY. dag_id=solar_flares_train_12h, task_id=train_notebook, run_id=scheduled__2025-08-12T00:00:00+00:00, execution_date=20250812T000000, start_date=20250812T131228, end_date=20250812T131329
[2025-08-12T13:13:29.709+0000] {standard_task_runner.py:110} ERROR - Failed to execute job 131 for task train_notebook (Bash command failed. The command returned a non-zero exit code 1.; 4247)
[2025-08-12T13:13:29.754+0000] {local_task_job_runner.py:240} INFO - Task exited with return code 1
[2025-08-12T13:13:29.767+0000] {taskinstance.py:3503} INFO - 0 downstream tasks scheduled from follow-on schedule check
[2025-08-12T13:13:29.771+0000] {local_task_job_runner.py:222} INFO - ::endgroup::
