[2025-08-09T19:22:54.740+0000] {local_task_job_runner.py:120} INFO - ::group::Pre task execution logs
[2025-08-09T19:22:54.767+0000] {taskinstance.py:2076} INFO - Dependencies all met for dep_context=non-requeueable deps ti=<TaskInstance: xrs_update_12h.backfill_ncei_yesterday scheduled__2025-08-09T00:00:00+00:00 [queued]>
[2025-08-09T19:22:54.774+0000] {taskinstance.py:2076} INFO - Dependencies all met for dep_context=requeueable deps ti=<TaskInstance: xrs_update_12h.backfill_ncei_yesterday scheduled__2025-08-09T00:00:00+00:00 [queued]>
[2025-08-09T19:22:54.782+0000] {taskinstance.py:2306} INFO - Starting attempt 2 of 3
[2025-08-09T19:22:54.792+0000] {taskinstance.py:2330} INFO - Executing <Task(PythonOperator): backfill_ncei_yesterday> on 2025-08-09 00:00:00+00:00
[2025-08-09T19:22:54.800+0000] {standard_task_runner.py:90} INFO - Running: ['***', 'tasks', 'run', 'xrs_update_12h', 'backfill_ncei_yesterday', 'scheduled__2025-08-09T00:00:00+00:00', '--job-id', '51', '--raw', '--subdir', 'DAGS_FOLDER/xrs_update_daily.py', '--cfg-path', '/tmp/tmpxkwiys44']
[2025-08-09T19:22:54.801+0000] {logging_mixin.py:188} WARNING - /home/***/.local/lib/python3.12/site-packages/***/task/task_runner/standard_task_runner.py:61 DeprecationWarning: This process (pid=194) is multi-threaded, use of fork() may lead to deadlocks in the child.
[2025-08-09T19:22:54.802+0000] {standard_task_runner.py:91} INFO - Job 51: Subtask backfill_ncei_yesterday
[2025-08-09T19:22:54.802+0000] {standard_task_runner.py:63} INFO - Started process 195 to run task
[2025-08-09T19:22:54.848+0000] {task_command.py:426} INFO - Running <TaskInstance: xrs_update_12h.backfill_ncei_yesterday scheduled__2025-08-09T00:00:00+00:00 [running]> on host 9d4e07229e62
[2025-08-09T19:22:54.934+0000] {taskinstance.py:2648} INFO - Exporting env vars: AIRFLOW_CTX_DAG_OWNER='you' AIRFLOW_CTX_DAG_ID='xrs_update_12h' AIRFLOW_CTX_TASK_ID='backfill_ncei_yesterday' AIRFLOW_CTX_EXECUTION_DATE='2025-08-09T00:00:00+00:00' AIRFLOW_CTX_TRY_NUMBER='2' AIRFLOW_CTX_DAG_RUN_ID='scheduled__2025-08-09T00:00:00+00:00'
[2025-08-09T19:22:54.935+0000] {taskinstance.py:430} INFO - ::endgroup::
[2025-08-09T19:22:54.954+0000] {logging_mixin.py:188} INFO - â†’ Running (cwd=/opt/project): python src/data/xrs_update.py --mode backfill --start {{ (ds | ds_add(-1)) }} --end {{ (ds | ds_add(-1)) }}
[2025-08-09T19:22:55.033+0000] {taskinstance.py:441} INFO - ::group::Post task execution logs
[2025-08-09T19:22:55.034+0000] {taskinstance.py:2905} ERROR - Task failed with exception
Traceback (most recent call last):
  File "/home/airflow/.local/lib/python3.12/site-packages/airflow/models/taskinstance.py", line 465, in _execute_task
    result = _execute_callable(context=context, **execute_callable_kwargs)
             ^^^^^^^^^^^^^^^^^^^^^^^^^^^^^^^^^^^^^^^^^^^^^^^^^^^^^^^^^^^^^
  File "/home/airflow/.local/lib/python3.12/site-packages/airflow/models/taskinstance.py", line 432, in _execute_callable
    return execute_callable(context=context, **execute_callable_kwargs)
           ^^^^^^^^^^^^^^^^^^^^^^^^^^^^^^^^^^^^^^^^^^^^^^^^^^^^^^^^^^^^
  File "/home/airflow/.local/lib/python3.12/site-packages/airflow/models/baseoperator.py", line 401, in wrapper
    return func(self, *args, **kwargs)
           ^^^^^^^^^^^^^^^^^^^^^^^^^^^
  File "/home/airflow/.local/lib/python3.12/site-packages/airflow/operators/python.py", line 235, in execute
    return_value = self.execute_callable()
                   ^^^^^^^^^^^^^^^^^^^^^^^
  File "/home/airflow/.local/lib/python3.12/site-packages/airflow/operators/python.py", line 252, in execute_callable
    return self.python_callable(*self.op_args, **self.op_kwargs)
           ^^^^^^^^^^^^^^^^^^^^^^^^^^^^^^^^^^^^^^^^^^^^^^^^^^^^^
  File "/opt/airflow/dags/xrs_update_daily.py", line 30, in <lambda>
    python_callable=lambda: run([
                            ^^^^^
  File "/opt/airflow/dags/xrs_update_daily.py", line 13, in run
    raise RuntimeError(f"Command failed with code {p.returncode}")
RuntimeError: Command failed with code 2
[2025-08-09T19:22:55.047+0000] {taskinstance.py:1206} INFO - Marking task as UP_FOR_RETRY. dag_id=xrs_update_12h, task_id=backfill_ncei_yesterday, run_id=scheduled__2025-08-09T00:00:00+00:00, execution_date=20250809T000000, start_date=20250809T192254, end_date=20250809T192255
[2025-08-09T19:22:55.059+0000] {standard_task_runner.py:110} ERROR - Failed to execute job 51 for task backfill_ncei_yesterday (Command failed with code 2; 195)
[2025-08-09T19:22:55.096+0000] {local_task_job_runner.py:240} INFO - Task exited with return code 1
[2025-08-09T19:22:55.115+0000] {taskinstance.py:3503} INFO - 0 downstream tasks scheduled from follow-on schedule check
[2025-08-09T19:22:55.127+0000] {local_task_job_runner.py:222} INFO - ::endgroup::
[2025-08-09T19:31:40.541+0000] {local_task_job_runner.py:120} INFO - ::group::Pre task execution logs
[2025-08-09T19:31:40.574+0000] {taskinstance.py:2076} INFO - Dependencies all met for dep_context=non-requeueable deps ti=<TaskInstance: xrs_update_12h.backfill_ncei_yesterday scheduled__2025-08-09T00:00:00+00:00 [queued]>
[2025-08-09T19:31:40.581+0000] {taskinstance.py:2076} INFO - Dependencies all met for dep_context=requeueable deps ti=<TaskInstance: xrs_update_12h.backfill_ncei_yesterday scheduled__2025-08-09T00:00:00+00:00 [queued]>
[2025-08-09T19:31:40.582+0000] {taskinstance.py:2306} INFO - Starting attempt 2 of 4
[2025-08-09T19:31:40.601+0000] {taskinstance.py:2330} INFO - Executing <Task(BashOperator): backfill_ncei_yesterday> on 2025-08-09 00:00:00+00:00
[2025-08-09T19:31:40.609+0000] {standard_task_runner.py:90} INFO - Running: ['***', 'tasks', 'run', 'xrs_update_12h', 'backfill_ncei_yesterday', 'scheduled__2025-08-09T00:00:00+00:00', '--job-id', '54', '--raw', '--subdir', 'DAGS_FOLDER/xrs_update_daily.py', '--cfg-path', '/tmp/tmp9aieqfqh']
[2025-08-09T19:31:40.612+0000] {logging_mixin.py:188} WARNING - /home/***/.local/lib/python3.12/site-packages/***/task/task_runner/standard_task_runner.py:61 DeprecationWarning: This process (pid=272) is multi-threaded, use of fork() may lead to deadlocks in the child.
[2025-08-09T19:31:40.612+0000] {standard_task_runner.py:91} INFO - Job 54: Subtask backfill_ncei_yesterday
[2025-08-09T19:31:40.613+0000] {standard_task_runner.py:63} INFO - Started process 273 to run task
[2025-08-09T19:31:40.669+0000] {task_command.py:426} INFO - Running <TaskInstance: xrs_update_12h.backfill_ncei_yesterday scheduled__2025-08-09T00:00:00+00:00 [running]> on host 9d4e07229e62
[2025-08-09T19:31:40.729+0000] {abstractoperator.py:725} ERROR - Exception rendering Jinja template for task 'backfill_ncei_yesterday', field 'bash_command'. Template: 'python /opt/project/src/data/xrs_update.py --mode backfill --start {{ (ds | ds_add(-1)) }} --end {{ (ds | ds_add(-1)) }}'
Traceback (most recent call last):
  File "/home/airflow/.local/lib/python3.12/site-packages/airflow/models/abstractoperator.py", line 717, in _do_render_template_fields
    rendered_content = self.render_template(
                       ^^^^^^^^^^^^^^^^^^^^^
  File "/home/airflow/.local/lib/python3.12/site-packages/airflow/template/templater.py", line 168, in render_template
    template = jinja_env.from_string(value)
               ^^^^^^^^^^^^^^^^^^^^^^^^^^^^
  File "/home/airflow/.local/lib/python3.12/site-packages/jinja2/environment.py", line 1108, in from_string
    return cls.from_code(self, self.compile(source), gs, None)
                               ^^^^^^^^^^^^^^^^^^^^
  File "/home/airflow/.local/lib/python3.12/site-packages/jinja2/environment.py", line 768, in compile
    self.handle_exception(source=source_hint)
  File "/home/airflow/.local/lib/python3.12/site-packages/jinja2/environment.py", line 939, in handle_exception
    raise rewrite_traceback_stack(source=source)
  File "<unknown>", line 1, in template
jinja2.exceptions.TemplateAssertionError: No filter named 'ds_add'.
[2025-08-09T19:31:40.731+0000] {taskinstance.py:2905} ERROR - Task failed with exception
Traceback (most recent call last):
  File "/home/airflow/.local/lib/python3.12/site-packages/airflow/models/taskinstance.py", line 2479, in _run_raw_task
    self._execute_task_with_callbacks(context, test_mode, session=session)
  File "/home/airflow/.local/lib/python3.12/site-packages/airflow/models/taskinstance.py", line 2633, in _execute_task_with_callbacks
    task_orig = self.render_templates(context=context, jinja_env=jinja_env)
                ^^^^^^^^^^^^^^^^^^^^^^^^^^^^^^^^^^^^^^^^^^^^^^^^^^^^^^^^^^^
  File "/home/airflow/.local/lib/python3.12/site-packages/airflow/models/taskinstance.py", line 3094, in render_templates
    original_task.render_template_fields(context, jinja_env)
  File "/home/airflow/.local/lib/python3.12/site-packages/airflow/models/baseoperator.py", line 1337, in render_template_fields
    self._do_render_template_fields(self, self.template_fields, context, jinja_env, set())
  File "/home/airflow/.local/lib/python3.12/site-packages/airflow/models/abstractoperator.py", line 717, in _do_render_template_fields
    rendered_content = self.render_template(
                       ^^^^^^^^^^^^^^^^^^^^^
  File "/home/airflow/.local/lib/python3.12/site-packages/airflow/template/templater.py", line 168, in render_template
    template = jinja_env.from_string(value)
               ^^^^^^^^^^^^^^^^^^^^^^^^^^^^
  File "/home/airflow/.local/lib/python3.12/site-packages/jinja2/environment.py", line 1108, in from_string
    return cls.from_code(self, self.compile(source), gs, None)
                               ^^^^^^^^^^^^^^^^^^^^
  File "/home/airflow/.local/lib/python3.12/site-packages/jinja2/environment.py", line 768, in compile
    self.handle_exception(source=source_hint)
  File "/home/airflow/.local/lib/python3.12/site-packages/jinja2/environment.py", line 939, in handle_exception
    raise rewrite_traceback_stack(source=source)
  File "<unknown>", line 1, in template
jinja2.exceptions.TemplateAssertionError: No filter named 'ds_add'.
[2025-08-09T19:31:40.744+0000] {taskinstance.py:1206} INFO - Marking task as UP_FOR_RETRY. dag_id=xrs_update_12h, task_id=backfill_ncei_yesterday, run_id=scheduled__2025-08-09T00:00:00+00:00, execution_date=20250809T000000, start_date=20250809T193140, end_date=20250809T193140
[2025-08-09T19:31:40.756+0000] {standard_task_runner.py:110} ERROR - Failed to execute job 54 for task backfill_ncei_yesterday (No filter named 'ds_add'.; 273)
[2025-08-09T19:31:40.786+0000] {local_task_job_runner.py:240} INFO - Task exited with return code 1
[2025-08-09T19:31:40.806+0000] {taskinstance.py:3503} INFO - 0 downstream tasks scheduled from follow-on schedule check
[2025-08-09T19:31:40.816+0000] {local_task_job_runner.py:222} INFO - ::endgroup::
