[2025-08-14T00:43:09.461+0000] {local_task_job_runner.py:120} INFO - ::group::Pre task execution logs
[2025-08-14T00:43:09.560+0000] {taskinstance.py:2076} INFO - Dependencies all met for dep_context=non-requeueable deps ti=<TaskInstance: xrs_update_12h.update_swpc_recent scheduled__2025-08-13T00:00:00+00:00 [queued]>
[2025-08-14T00:43:09.575+0000] {taskinstance.py:2076} INFO - Dependencies all met for dep_context=requeueable deps ti=<TaskInstance: xrs_update_12h.update_swpc_recent scheduled__2025-08-13T00:00:00+00:00 [queued]>
[2025-08-14T00:43:09.578+0000] {taskinstance.py:2306} INFO - Starting attempt 2 of 3
[2025-08-14T00:43:09.614+0000] {taskinstance.py:2330} INFO - Executing <Task(BashOperator): update_swpc_recent> on 2025-08-13 00:00:00+00:00
[2025-08-14T00:43:09.643+0000] {standard_task_runner.py:90} INFO - Running: ['***', 'tasks', 'run', 'xrs_update_12h', 'update_swpc_recent', 'scheduled__2025-08-13T00:00:00+00:00', '--job-id', '170', '--raw', '--subdir', 'DAGS_FOLDER/xrs_update_daily.py', '--cfg-path', '/tmp/tmp6rq40_tz']
[2025-08-14T00:43:09.647+0000] {standard_task_runner.py:91} INFO - Job 170: Subtask update_swpc_recent
[2025-08-14T00:43:09.648+0000] {logging_mixin.py:188} WARNING - /home/***/.local/lib/python3.12/site-packages/***/task/task_runner/standard_task_runner.py:61 DeprecationWarning: This process (pid=6359) is multi-threaded, use of fork() may lead to deadlocks in the child.
[2025-08-14T00:43:09.649+0000] {standard_task_runner.py:63} INFO - Started process 6366 to run task
[2025-08-14T00:43:09.782+0000] {task_command.py:426} INFO - Running <TaskInstance: xrs_update_12h.update_swpc_recent scheduled__2025-08-13T00:00:00+00:00 [running]> on host def4e694b617
[2025-08-14T00:43:09.993+0000] {taskinstance.py:2648} INFO - Exporting env vars: AIRFLOW_CTX_DAG_OWNER='you' AIRFLOW_CTX_DAG_ID='xrs_update_12h' AIRFLOW_CTX_TASK_ID='update_swpc_recent' AIRFLOW_CTX_EXECUTION_DATE='2025-08-13T00:00:00+00:00' AIRFLOW_CTX_TRY_NUMBER='2' AIRFLOW_CTX_DAG_RUN_ID='scheduled__2025-08-13T00:00:00+00:00'
[2025-08-14T00:43:09.996+0000] {taskinstance.py:430} INFO - ::endgroup::
[2025-08-14T00:43:10.046+0000] {subprocess.py:63} INFO - Tmp dir root location: /tmp
[2025-08-14T00:43:10.058+0000] {subprocess.py:75} INFO - Running command: ['/usr/bin/bash', '-c', 'python /opt/project/src/data/xrs_update.py --mode update --since-minutes 20160 --keep-days 180']
[2025-08-14T00:43:10.086+0000] {subprocess.py:86} INFO - Output:
[2025-08-14T00:43:12.941+0000] {subprocess.py:93} INFO - Traceback (most recent call last):
[2025-08-14T00:43:12.943+0000] {subprocess.py:93} INFO -   File "/home/***/.local/lib/python3.12/site-packages/urllib3/connection.py", line 198, in _new_conn
[2025-08-14T00:43:12.944+0000] {subprocess.py:93} INFO -     sock = connection.create_connection(
[2025-08-14T00:43:12.945+0000] {subprocess.py:93} INFO -            ^^^^^^^^^^^^^^^^^^^^^^^^^^^^^
[2025-08-14T00:43:12.945+0000] {subprocess.py:93} INFO -   File "/home/***/.local/lib/python3.12/site-packages/urllib3/util/connection.py", line 60, in create_connection
[2025-08-14T00:43:12.946+0000] {subprocess.py:93} INFO -     for res in socket.getaddrinfo(host, port, family, socket.SOCK_STREAM):
[2025-08-14T00:43:12.946+0000] {subprocess.py:93} INFO -                ^^^^^^^^^^^^^^^^^^^^^^^^^^^^^^^^^^^^^^^^^^^^^^^^^^^^^^^^^^
[2025-08-14T00:43:12.947+0000] {subprocess.py:93} INFO -   File "/usr/local/lib/python3.12/socket.py", line 964, in getaddrinfo
[2025-08-14T00:43:12.947+0000] {subprocess.py:93} INFO -     for res in _socket.getaddrinfo(host, port, family, type, proto, flags):
[2025-08-14T00:43:12.948+0000] {subprocess.py:93} INFO -                ^^^^^^^^^^^^^^^^^^^^^^^^^^^^^^^^^^^^^^^^^^^^^^^^^^^^^^^^^^^
[2025-08-14T00:43:12.948+0000] {subprocess.py:93} INFO - socket.gaierror: [Errno -2] Name or service not known
[2025-08-14T00:43:12.949+0000] {subprocess.py:93} INFO - 
[2025-08-14T00:43:12.950+0000] {subprocess.py:93} INFO - The above exception was the direct cause of the following exception:
[2025-08-14T00:43:12.951+0000] {subprocess.py:93} INFO - 
[2025-08-14T00:43:12.952+0000] {subprocess.py:93} INFO - Traceback (most recent call last):
[2025-08-14T00:43:12.952+0000] {subprocess.py:93} INFO -   File "/home/***/.local/lib/python3.12/site-packages/urllib3/connectionpool.py", line 793, in urlopen
[2025-08-14T00:43:12.953+0000] {subprocess.py:93} INFO -     response = self._make_request(
[2025-08-14T00:43:12.953+0000] {subprocess.py:93} INFO -                ^^^^^^^^^^^^^^^^^^^
[2025-08-14T00:43:12.954+0000] {subprocess.py:93} INFO -   File "/home/***/.local/lib/python3.12/site-packages/urllib3/connectionpool.py", line 491, in _make_request
[2025-08-14T00:43:12.955+0000] {subprocess.py:93} INFO -     raise new_e
[2025-08-14T00:43:12.955+0000] {subprocess.py:93} INFO -   File "/home/***/.local/lib/python3.12/site-packages/urllib3/connectionpool.py", line 467, in _make_request
[2025-08-14T00:43:12.956+0000] {subprocess.py:93} INFO -     self._validate_conn(conn)
[2025-08-14T00:43:12.956+0000] {subprocess.py:93} INFO -   File "/home/***/.local/lib/python3.12/site-packages/urllib3/connectionpool.py", line 1099, in _validate_conn
[2025-08-14T00:43:12.957+0000] {subprocess.py:93} INFO -     conn.connect()
[2025-08-14T00:43:12.958+0000] {subprocess.py:93} INFO -   File "/home/***/.local/lib/python3.12/site-packages/urllib3/connection.py", line 616, in connect
[2025-08-14T00:43:12.959+0000] {subprocess.py:93} INFO -     self.sock = sock = self._new_conn()
[2025-08-14T00:43:12.960+0000] {subprocess.py:93} INFO -                        ^^^^^^^^^^^^^^^^
[2025-08-14T00:43:12.961+0000] {subprocess.py:93} INFO -   File "/home/***/.local/lib/python3.12/site-packages/urllib3/connection.py", line 205, in _new_conn
[2025-08-14T00:43:12.961+0000] {subprocess.py:93} INFO -     raise NameResolutionError(self.host, self, e) from e
[2025-08-14T00:43:12.962+0000] {subprocess.py:93} INFO - urllib3.exceptions.NameResolutionError: <urllib3.connection.HTTPSConnection object at 0x75b35d07a060>: Failed to resolve 'services.swpc.noaa.gov' ([Errno -2] Name or service not known)
[2025-08-14T00:43:12.962+0000] {subprocess.py:93} INFO - 
[2025-08-14T00:43:12.963+0000] {subprocess.py:93} INFO - The above exception was the direct cause of the following exception:
[2025-08-14T00:43:12.965+0000] {subprocess.py:93} INFO - 
[2025-08-14T00:43:12.965+0000] {subprocess.py:93} INFO - Traceback (most recent call last):
[2025-08-14T00:43:12.966+0000] {subprocess.py:93} INFO -   File "/home/***/.local/lib/python3.12/site-packages/requests/adapters.py", line 667, in send
[2025-08-14T00:43:12.967+0000] {subprocess.py:93} INFO -     resp = conn.urlopen(
[2025-08-14T00:43:12.967+0000] {subprocess.py:93} INFO -            ^^^^^^^^^^^^^
[2025-08-14T00:43:12.968+0000] {subprocess.py:93} INFO -   File "/home/***/.local/lib/python3.12/site-packages/urllib3/connectionpool.py", line 847, in urlopen
[2025-08-14T00:43:12.968+0000] {subprocess.py:93} INFO -     retries = retries.increment(
[2025-08-14T00:43:12.969+0000] {subprocess.py:93} INFO -               ^^^^^^^^^^^^^^^^^^
[2025-08-14T00:43:12.969+0000] {subprocess.py:93} INFO -   File "/home/***/.local/lib/python3.12/site-packages/urllib3/util/retry.py", line 515, in increment
[2025-08-14T00:43:12.970+0000] {subprocess.py:93} INFO -     raise MaxRetryError(_pool, url, reason) from reason  # type: ignore[arg-type]
[2025-08-14T00:43:12.971+0000] {subprocess.py:93} INFO -     ^^^^^^^^^^^^^^^^^^^^^^^^^^^^^^^^^^^^^^^^^^^^^^^^^^^
[2025-08-14T00:43:12.971+0000] {subprocess.py:93} INFO - urllib3.exceptions.MaxRetryError: HTTPSConnectionPool(host='services.swpc.noaa.gov', port=443): Max retries exceeded with url: /json/goes/primary/xrays-7-day.json (Caused by NameResolutionError("<urllib3.connection.HTTPSConnection object at 0x75b35d07a060>: Failed to resolve 'services.swpc.noaa.gov' ([Errno -2] Name or service not known)"))
[2025-08-14T00:43:12.972+0000] {subprocess.py:93} INFO - 
[2025-08-14T00:43:12.973+0000] {subprocess.py:93} INFO - During handling of the above exception, another exception occurred:
[2025-08-14T00:43:12.973+0000] {subprocess.py:93} INFO - 
[2025-08-14T00:43:12.974+0000] {subprocess.py:93} INFO - Traceback (most recent call last):
[2025-08-14T00:43:12.975+0000] {subprocess.py:93} INFO -   File "/opt/project/src/data/xrs_update.py", line 387, in <module>
[2025-08-14T00:43:12.975+0000] {subprocess.py:93} INFO -     main()
[2025-08-14T00:43:12.976+0000] {subprocess.py:93} INFO -   File "/opt/project/src/data/xrs_update.py", line 384, in main
[2025-08-14T00:43:12.976+0000] {subprocess.py:93} INFO -     update_since(args.since_minutes, args.keep_days)
[2025-08-14T00:43:12.977+0000] {subprocess.py:93} INFO -   File "/opt/project/src/data/xrs_update.py", line 354, in update_since
[2025-08-14T00:43:12.978+0000] {subprocess.py:93} INFO -     df = _fetch_swpc_json(minutes=minutes)
[2025-08-14T00:43:12.979+0000] {subprocess.py:93} INFO -          ^^^^^^^^^^^^^^^^^^^^^^^^^^^^^^^^^
[2025-08-14T00:43:12.979+0000] {subprocess.py:93} INFO -   File "/opt/project/src/data/xrs_update.py", line 166, in _fetch_swpc_json
[2025-08-14T00:43:12.980+0000] {subprocess.py:93} INFO -     r = requests.get(url, timeout=30)
[2025-08-14T00:43:12.980+0000] {subprocess.py:93} INFO -         ^^^^^^^^^^^^^^^^^^^^^^^^^^^^^
[2025-08-14T00:43:12.981+0000] {subprocess.py:93} INFO -   File "/home/***/.local/lib/python3.12/site-packages/requests/api.py", line 73, in get
[2025-08-14T00:43:12.981+0000] {subprocess.py:93} INFO -     return request("get", url, params=params, **kwargs)
[2025-08-14T00:43:12.982+0000] {subprocess.py:93} INFO -            ^^^^^^^^^^^^^^^^^^^^^^^^^^^^^^^^^^^^^^^^^^^^
[2025-08-14T00:43:12.982+0000] {subprocess.py:93} INFO -   File "/home/***/.local/lib/python3.12/site-packages/requests/api.py", line 59, in request
[2025-08-14T00:43:12.983+0000] {subprocess.py:93} INFO -     return session.request(method=method, url=url, **kwargs)
[2025-08-14T00:43:12.983+0000] {subprocess.py:93} INFO -            ^^^^^^^^^^^^^^^^^^^^^^^^^^^^^^^^^^^^^^^^^^^^^^^^^
[2025-08-14T00:43:12.984+0000] {subprocess.py:93} INFO -   File "/home/***/.local/lib/python3.12/site-packages/requests/sessions.py", line 589, in request
[2025-08-14T00:43:12.984+0000] {subprocess.py:93} INFO -     resp = self.send(prep, **send_kwargs)
[2025-08-14T00:43:12.985+0000] {subprocess.py:93} INFO -            ^^^^^^^^^^^^^^^^^^^^^^^^^^^^^^
[2025-08-14T00:43:12.986+0000] {subprocess.py:93} INFO -   File "/home/***/.local/lib/python3.12/site-packages/requests/sessions.py", line 703, in send
[2025-08-14T00:43:12.986+0000] {subprocess.py:93} INFO -     r = adapter.send(request, **kwargs)
[2025-08-14T00:43:12.987+0000] {subprocess.py:93} INFO -         ^^^^^^^^^^^^^^^^^^^^^^^^^^^^^^^
[2025-08-14T00:43:12.987+0000] {subprocess.py:93} INFO -   File "/home/***/.local/lib/python3.12/site-packages/requests/adapters.py", line 700, in send
[2025-08-14T00:43:12.988+0000] {subprocess.py:93} INFO -     raise ConnectionError(e, request=request)
[2025-08-14T00:43:12.988+0000] {subprocess.py:93} INFO - requests.exceptions.ConnectionError: HTTPSConnectionPool(host='services.swpc.noaa.gov', port=443): Max retries exceeded with url: /json/goes/primary/xrays-7-day.json (Caused by NameResolutionError("<urllib3.connection.HTTPSConnection object at 0x75b35d07a060>: Failed to resolve 'services.swpc.noaa.gov' ([Errno -2] Name or service not known)"))
[2025-08-14T00:43:13.177+0000] {subprocess.py:97} INFO - Command exited with return code 1
[2025-08-14T00:43:13.181+0000] {taskinstance.py:441} INFO - ::group::Post task execution logs
[2025-08-14T00:43:13.208+0000] {taskinstance.py:2905} ERROR - Task failed with exception
Traceback (most recent call last):
  File "/home/airflow/.local/lib/python3.12/site-packages/airflow/models/taskinstance.py", line 460, in _execute_task
    result = _execute_callable(context=context, **execute_callable_kwargs)
             ^^^^^^^^^^^^^^^^^^^^^^^^^^^^^^^^^^^^^^^^^^^^^^^^^^^^^^^^^^^^^
  File "/home/airflow/.local/lib/python3.12/site-packages/airflow/models/taskinstance.py", line 432, in _execute_callable
    return execute_callable(context=context, **execute_callable_kwargs)
           ^^^^^^^^^^^^^^^^^^^^^^^^^^^^^^^^^^^^^^^^^^^^^^^^^^^^^^^^^^^^
  File "/home/airflow/.local/lib/python3.12/site-packages/airflow/models/baseoperator.py", line 401, in wrapper
    return func(self, *args, **kwargs)
           ^^^^^^^^^^^^^^^^^^^^^^^^^^^
  File "/home/airflow/.local/lib/python3.12/site-packages/airflow/operators/bash.py", line 243, in execute
    raise AirflowException(
airflow.exceptions.AirflowException: Bash command failed. The command returned a non-zero exit code 1.
[2025-08-14T00:43:13.216+0000] {taskinstance.py:1206} INFO - Marking task as UP_FOR_RETRY. dag_id=xrs_update_12h, task_id=update_swpc_recent, run_id=scheduled__2025-08-13T00:00:00+00:00, execution_date=20250813T000000, start_date=20250814T004309, end_date=20250814T004313
[2025-08-14T00:43:13.241+0000] {standard_task_runner.py:110} ERROR - Failed to execute job 170 for task update_swpc_recent (Bash command failed. The command returned a non-zero exit code 1.; 6366)
[2025-08-14T00:43:13.289+0000] {local_task_job_runner.py:240} INFO - Task exited with return code 1
[2025-08-14T00:43:13.316+0000] {taskinstance.py:3503} INFO - 0 downstream tasks scheduled from follow-on schedule check
[2025-08-14T00:43:13.319+0000] {local_task_job_runner.py:222} INFO - ::endgroup::
